Workbook

Sheet Servicios
A1: O1 | B1: Retina
A2: O2 | B2: Glaucoma
A3: O3 | B3: Oculoplastia
A4: O4 | B4: Cornea y segemento
A5: O5 | B5: Estrabología y pediatría
A6: O6 | B6: Oftalmología paquete
A7: O7 | B7: Pre retina
A8: O8 | B8: Pre glaucoma
A9: O9 | B9: Oftalmología normal
A10: O10 | B10: Anamnesis
A11: O11 | B11: Constroles consulta
A12: O12 | B12: Controles Post
... A54: U3 | B54: Optometría UIS

Sheet Trabajadores
A1: ="T"&_xlfn.SEQUENCE(36,1,1,1) -> T1 | B1: LUIS MIGUEL GIRON
A2: T2 | B2: DIEGO GUARIN
A3: T3 | B3: NICOHOL ANDRES TOVAR
A4: T4 | B4: MARYUDI VELANDIA
A5: T5 | B5: GERMAN HERNANDEZ
A6: T6 | B6: ADRIANA BAYONA
A7: T7 | B7: JOSE LUIS MEJIA
A8: T8 | B8: LUIS EDUARDO PAZ
A9: T9 | B9: ANA SANMIGUEL
A10: T10 | B10: NATALIA CORREA
A11: T11 | B11: TERESA ORDOÑEZ
A12: T12 | B12: MARIA CAMILA PLATA
A13: T13 | B13: SERGIO MORENO
... A45: T45 | B45: PRACTICANTE 5

Sheet Consultorios
B1: S1 | C1: S2 | D1: S3 | E1: S4 | F1: S5
A2: C1 | B2: Consultorio 2 | C2: SIAU | D2: Consultorio 1 | E2: Consultorio 1 | F2: Consultorio 1
A3: C2 | B3: Consultorio 3 | C3: Consultorio 1 | D3: Consultorio 2 | E3: Consultorio 2 | F3: Consultorio 2
A4: C3 | B4: Consultorio 4 | C4: Consultorio 2 | D4: Consultorio 3 | E4: Consultorio 3 | F4: Consultorio 3
A5: C4 | B5: Consultorio 5 | C5: Consultorio 3 | D5: Consultiorio 4 | E5: NA | F5: NA
A6: C5 | B6: Consultorio 18 | C6: Consultorio 4 | D6: NA | E6: NA | F6: NA
A7: C6 | B7: Consultorio 19 | C7: Consultorio 5 | D7: NA | E7: NA | F7: NA
A8: C7 | B8: Consultorio 20 | C8: Consultorio 6 | D8: NA | E8: NA | F8: NA
A9: C8 | B9: Consultorio 22 | C9: Consultorio 7 | D9: NA | E9: NA | F9: NA
A10: C9 | B10: Quirofano 1 | C10: Consultorio 8 | D10: NA | E10: NA | F10: NA
A11: C10 | B11: Quirofano 2 | C11: Consultorio 9 | D11: NA | E11: NA | F11: NA
A12: C11 | B12: Consultorio 21 (Spa) | C12: NA | D12: NA | E12: NA | F12: NA
A13: C12 | B13: Consultorio 7 | C13: NA | D13: NA | E13: NA | F13: NA

Sheet Presencia_sede
B1: S1 | C1: S2 | D1: S3 | E1: S4 | F1: S5
A2: ="T"&_xlfn.SEQUENCE(36,1,1,1) -> T1 | B2: 1 | C2: 1 | D2: 1 | E2: 0 | F2: 1
A3: T2 | B3: 1 | C3: 1 | D3: 1 | E3: 0 | F3: 0
A4: T3 | B4: 1 | C4: 1 | D4: 1 | E4: 1 | F4: 0
A5: T4 | B5: 1 | C5: 1 | D5: 1 | E5: 0 | F5: 0
A6: T5 | B6: 1 | C6: 1 | D6: 0 | E6: 1 | F6: 0
A7: T6 | B7: 1 | C7: 1 | D7: 1 | E7: 1 | F7: 0
A8: T7 | B8: 1 | C8: 1 | D8: 1 | E8: 0 | F8: 1
A9: T8 | B9: 1 | C9: 1 | D9: 1 | E9: 0 | F9: 1
A10: T9 | B10: 1 | C10: 1 | D10: 0 | E10: 0 | F10: 0
A11: T10 | B11: 1 | C11: 1 | D11: 0 | E11: 1 | F11: 0
A12: T11 | B12: 1 | C12: 1 | D12: 1 | E12: 0 | F12: 0
A13: T12 | B13: 1 | C13: 1 | D13: 0 | E13: 1 | F13: 0
A14: T13 | B14: 1 | C14: 0 | D14: 0 | E14: 0 | F14: 0
... A46: T45 | B46: 1 | C46: 1 | D46: 1 | E46: 0 | F46: 0

Sheet Habilidad
B1: Sede1 | C1: Sede2 | D1: Sede3 | E1: Sede4 | F1: Sede 5
A2: T1 | B2: =+Presencia_sede!B2 -> 1 | C2: =+Presencia_sede!C2 -> 1 | D2: =+Presencia_sede!D2 -> 1 | E2: =+Presencia_sede!E2 -> 0 | F2: =+Presencia_sede!F2 -> 1
A3: T2 | B3: =+Presencia_sede!B3 -> 1 | C3: =+Presencia_sede!C3 -> 1 | D3: =+Presencia_sede!D3 -> 1 | E3: =+Presencia_sede!E3 -> 0 | F3: =+Presencia_sede!F3 -> 0
A4: T3 | B4: =+Presencia_sede!B4 -> 1 | C4: =+Presencia_sede!C4 -> 1 | D4: =+Presencia_sede!D4 -> 1 | E4: =+Presencia_sede!E4 -> 1 | F4: =+Presencia_sede!F4 -> 0
A5: T4 | B5: =+Presencia_sede!B5 -> 1 | C5: =+Presencia_sede!C5 -> 1 | D5: =+Presencia_sede!D5 -> 1 | E5: =+Presencia_sede!E5 -> 0 | F5: =+Presencia_sede!F5 -> 0
A6: T5 | B6: =+Presencia_sede!B6 -> 1 | C6: =+Presencia_sede!C6 -> 1 | D6: =+Presencia_sede!D6 -> 0 | E6: =+Presencia_sede!E6 -> 1 | F6: =+Presencia_sede!F6 -> 0
A7: T6 | B7: =+Presencia_sede!B7 -> 1 | C7: =+Presencia_sede!C7 -> 1 | D7: =+Presencia_sede!D7 -> 1 | E7: =+Presencia_sede!E7 -> 1 | F7: =+Presencia_sede!F7 -> 0
A8: T7 | B8: =+Presencia_sede!B8 -> 1 | C8: =+Presencia_sede!C8 -> 1 | D8: =+Presencia_sede!D8 -> 1 | E8: =+Presencia_sede!E8 -> 0 | F8: =+Presencia_sede!F8 -> 1
A9: T8 | B9: =+Presencia_sede!B9 -> 1 | C9: =+Presencia_sede!C9 -> 1 | D9: =+Presencia_sede!D9 -> 1 | E9: =+Presencia_sede!E9 -> 0 | F9: =+Presencia_sede!F9 -> 1
A10: T9 | B10: =+Presencia_sede!B10 -> 1 | C10: =+Presencia_sede!C10 -> 1 | D10: =+Presencia_sede!D10 -> 0 | E10: =+Presencia_sede!E10 -> 0 | F10: =+Presencia_sede!F10 -> 0
A11: T10 | B11: =+Presencia_sede!B11 -> 1 | C11: =+Presencia_sede!C11 -> 1 | D11: =+Presencia_sede!D11 -> 0 | E11: =+Presencia_sede!E11 -> 1 | F11: =+Presencia_sede!F11 -> 0
A12: T11 | B12: =+Presencia_sede!B12 -> 1 | C12: =+Presencia_sede!C12 -> 1 | D12: =+Presencia_sede!D12 -> 1 | E12: =+Presencia_sede!E12 -> 0 | F12: =+Presencia_sede!F12 -> 0
A13: T12 | B13: =+Presencia_sede!B13 -> 1 | C13: =+Presencia_sede!C13 -> 1 | D13: =+Presencia_sede!D13 -> 0 | E13: =+Presencia_sede!E13 -> 1 | F13: =+Presencia_sede!F13 -> 0
... A46: T45 | B46: =+Presencia_sede!B46 -> 1 | C46: =+Presencia_sede!C46 -> 1 | D46: =+Presencia_sede!D46 -> 1 | E46: =+Presencia_sede!E46 -> 0 | F46: =+Presencia_sede!F46 -> 0

Sheet FORM
B1: [Jueves 01/01/2026] | C1: [Viernes 02/01/2026] | D1: [Sábado 03/01/2026] | E1: Domingo | F1: [Lunes 05/01/2026] | G1: [Martes 06/01/2026] | H1: [Miércoles 07/01/2026] | I1: [Jueves 08/01/2026] | J1: [Viernes 09/01/2026] | K1: [Sábado 10/01/2026] | L1: Domingo | M1: [Lunes 12/01/2026] | N1: [Martes 13/01/2026] | O1: [Miércoles 14/01/2026] | P1: [Jueves 15/01/2026] | Q1: [Viernes 16/01/2026] | R1: [Sábado 17/01/2026] | S1: Domingo | T1: [Lunes 19/01/2026] | U1: [Martes 20/01/2026] | V1: [Miércoles 21/01/2026] | W1: [Jueves 22/01/2026] | X1: [Viernes 23/01/2026] | Y1: [Sábado 24/01/2026] | Z1: Domingo | AA1: [Lunes 26/01/2026] | AB1: [Martes 27/01/2026] | AC1: [Miércoles 28/01/2026] | AD1: [Jueves 29/01/2026] | AE1: [Viernes 30/01/2026] | AF1: [Sábado 31/01/2026]
A2: T01 | B2: NO ASISTE | C2: NO ASISTE | D2: NO ASISTE | E2: NO ASISTE | F2: AM Y PM | G2: AM Y PM | H2: AM Y PM | I2: AM Y PM | J2: AM Y PM | K2: NO ASISTE | L2: NO ASISTE | M2: NO ASISTE | N2: AM Y PM | O2: AM Y PM | P2: AM Y PM | Q2: AM Y PM | R2: NO ASISTE | S2: NO ASISTE | T2: AM Y PM | U2: AM Y PM | V2: AM Y PM | W2: AM Y PM | X2: AM | Y2: NO ASISTE | Z2: NO ASISTE | AA2: NO ASISTE | AB2: AM Y PM | AC2: AM Y PM | AD2: AM Y PM | AE2: AM Y PM | AF2: NO ASISTE
A3: T02 | B3: NO ASISTE | C3: NO ASISTE | D3: NO ASISTE | E3: NO ASISTE | F3: AM Y PM | G3: AM Y PM | H3: AM Y PM | I3: AM Y PM | J3: AM Y PM | K3: NO ASISTE | L3: NO ASISTE | M3: NO ASISTE | N3: AM Y PM | O3: AM Y PM | P3: AM Y PM | Q3: AM Y PM | R3: AM | S3: NO ASISTE | T3: AM Y PM | U3: AM Y PM | V3: AM Y PM | W3: AM Y PM | X3: AM Y PM | Y3: AM | Z3: NO ASISTE | AA3: AM Y PM | AB3: AM Y PM | AC3: AM Y PM | AD3: AM Y PM | AE3: AM Y PM | AF3: NO ASISTE
A4: T03 | B4: NO ASISTE | C4: NO ASISTE | D4: NO ASISTE | E4: NO ASISTE | F4: AM Y PM | G4: AM Y PM | H4: AM Y PM | I4: AM Y PM | J4: AM Y PM | K4: NO ASISTE | L4: NO ASISTE | M4: NO ASISTE | N4: AM Y PM | O4: AM Y PM | P4: AM Y PM | Q4: AM Y PM | R4: NO ASISTE | S4: NO ASISTE | T4: AM Y PM | U4: AM Y PM | V4: AM Y PM | W4: AM Y PM | X4: AM Y PM | Y4: NO ASISTE | Z4: NO ASISTE | AA4: AM Y PM | AB4: AM Y PM | AC4: AM Y PM | AD4: AM Y PM | AE4: AM Y PM | AF4: NO ASISTE
A5: T04 | B5: NO ASISTE | C5: NO ASISTE | D5: NO ASISTE | E5: NO ASISTE | F5: NO ASISTE | G5: AM Y PM | H5: AM Y PM | I5: AM Y PM | J5: AM Y PM | K5: NO ASISTE | L5: NO ASISTE | M5: NO ASISTE | N5: AM Y PM | O5: AM Y PM | P5: AM Y PM | Q5: AM Y PM | R5: NO ASISTE | S5: NO ASISTE | T5: AM Y PM | U5: AM Y PM | V5: AM Y PM | W5: AM Y PM | X5: AM | Y5: NO ASISTE | Z5: NO ASISTE | AA5: AM Y PM | AB5: AM Y PM | AC5: AM Y PM | AD5: AM Y PM | AE5: AM | AF5: NO ASISTE
A6: T05 | B6: NO ASISTE | C6: NO ASISTE | D6: NO ASISTE | E6: NO ASISTE | F6: NO ASISTE | G6: NO ASISTE | H6: NO ASISTE | I6: NO ASISTE | J6: NO ASISTE | K6: NO ASISTE | L6: NO ASISTE | M6: NO ASISTE | N6: NO ASISTE | O6: NO ASISTE | P6: NO ASISTE | Q6: NO ASISTE | R6: NO ASISTE | S6: NO ASISTE | T6: NO ASISTE | U6: NO ASISTE | V6: NO ASISTE | W6: NO ASISTE | X6: NO ASISTE | Y6: NO ASISTE | Z6: NO ASISTE | AA6: NO ASISTE | AB6: NO ASISTE | AC6: NO ASISTE | AD6: NO ASISTE | AE6: NO ASISTE | AF6: NO ASISTE
A7: T06 | B7: NO ASISTE | C7: NO ASISTE | D7: NO ASISTE | E7: NO ASISTE | F7: NO ASISTE | G7: AM Y PM | H7: AM Y PM | I7: AM Y PM | J7: AM Y PM | K7: AM | L7: NO ASISTE | M7: NO ASISTE | N7: AM Y PM | O7: AM Y PM | P7: AM Y PM | Q7: PM | R7: AM | S7: NO ASISTE | T7: AM Y PM | U7: AM Y PM | V7: AM Y PM | W7: AM Y PM | X7: AM Y PM | Y7: NO ASISTE | Z7: NO ASISTE | AA7: AM Y PM | AB7: AM Y PM | AC7: AM Y PM | AD7: AM Y PM | AE7: AM Y PM | AF7: AM
A8: T07 | B8: NO ASISTE | C8: NO ASISTE | D8: NO ASISTE | E8: NO ASISTE | F8: AM Y PM | G8: AM Y PM | H8: AM Y PM | I8: AM Y PM | J8: AM Y PM | K8: AM | L8: NO ASISTE | M8: NO ASISTE | N8: AM Y PM | O8: AM Y PM | P8: AM Y PM | Q8: AM Y PM | R8: AM | S8: NO ASISTE | T8: AM Y PM | U8: AM Y PM | V8: AM Y PM | W8: AM Y PM | X8: AM Y PM | Y8: NO ASISTE | Z8: NO ASISTE | AA8: NO ASISTE | AB8: NO ASISTE | AC8: NO ASISTE | AD8: NO ASISTE | AE8: NO ASISTE | AF8: NO ASISTE
A9: T08 | B9: NO ASISTE | C9: NO ASISTE | D9: NO ASISTE | E9: NO ASISTE | F9: NO ASISTE | G9: AM Y PM | H9: AM Y PM | I9: AM Y PM | J9: AM Y PM | K9: AM | L9: NO ASISTE | M9: NO ASISTE | N9: AM Y PM | O9: AM Y PM | P9: AM Y PM | Q9: AM Y PM | R9: AM | S9: NO ASISTE | T9: AM Y PM | U9: AM Y PM | V9: AM Y PM | W9: AM Y PM | X9: AM Y PM | Y9: AM | Z9: NO ASISTE | AA9: AM Y PM | AB9: AM Y PM | AC9: AM Y PM | AD9: AM Y PM | AE9: AM Y PM | AF9: AM
A10: T09 | B10: NO ASISTE | C10: NO ASISTE | D10: NO ASISTE | E10: NO ASISTE | F10: NO ASISTE | G10: AM | H10: AM | I10: AM | J10: NO ASISTE | K10: NO ASISTE | L10: NO ASISTE | M10: NO ASISTE | N10: AM Y PM | O10: AM Y PM | P10: AM Y PM | Q10: AM | R10: AM | S10: NO ASISTE | T10: AM | U10: AM | V10: NO ASISTE | W10: NO ASISTE | X10: NO ASISTE | Y10: NO ASISTE | Z10: NO ASISTE | AA10: AM Y PM | AB10: AM Y PM | AC10: AM Y PM | AD10: AM Y PM | AE10: AM | AF10: NO ASISTE
A11: T10 | B11: NO ASISTE | C11: NO ASISTE | D11: NO ASISTE | E11: NO ASISTE | F11: NO ASISTE | G11: NO ASISTE | H11: NO ASISTE | I11: AM | J11: AM | K11: NO ASISTE | L11: NO ASISTE | M11: NO ASISTE | N11: PM | O11: AM Y PM | P11: AM | Q11: AM Y PM | R11: AM | S11: NO ASISTE | T11: PM | U11: NO ASISTE | V11: PM | W11: NO ASISTE | X11: NO ASISTE | Y11: NO ASISTE | Z11: NO ASISTE | AA11: PM | AB11: NO ASISTE | AC11: NO ASISTE | AD11: NO ASISTE | AE11: NO ASISTE | AF11: NO ASISTE
A12: T11 | B12: NO ASISTE | C12: NO ASISTE | D12: NO ASISTE | E12: NO ASISTE | F12: NO ASISTE | G12: NO ASISTE | H12: NO ASISTE | I12: AM Y PM | J12: AM Y PM | K12: NO ASISTE | L12: NO ASISTE | M12: NO ASISTE | N12: AM | O12: AM | P12: AM Y PM | Q12: AM Y PM | R12: NO ASISTE | S12: NO ASISTE | T12: AM Y PM | U12: AM Y PM | V12: AM Y PM | W12: AM Y PM | X12: AM Y PM | Y12: NO ASISTE | Z12: NO ASISTE | AA12: AM Y PM | AB12: AM Y PM | AC12: AM Y PM | AD12: AM Y PM | AE12: AM Y PM | AF12: NO ASISTE
A13: T12 | B13: NO ASISTE | C13: NO ASISTE | D13: NO ASISTE | E13: NO ASISTE | F13: AM | G13: AM Y PM | H13: AM Y PM | I13: NO ASISTE | J13: NO ASISTE | K13: NO ASISTE | L13: NO ASISTE | M13: NO ASISTE | N13: AM | O13: AM Y PM | P13: PM | Q13: AM Y PM | R13: NO ASISTE | S13: NO ASISTE | T13: AM | U13: AM Y PM | V13: AM | W13: PM | X13: AM Y PM | Y13: NO ASISTE | Z13: NO ASISTE | AA13: AM | AB13: AM Y PM | AC13: AM Y PM | AD13: NO ASISTE | AE13: AM Y PM | AF13: AM
... A46: T45 | B46: NO ASISTE | C46: NO ASISTE | D46: NO ASISTE | E46: NO ASISTE | F46: NO ASISTE | G46: NO ASISTE | H46: AM Y PM | I46: AM Y PM | J46: AM Y PM | K46: AM | L46: NO ASISTE | M46: NO ASISTE | N46: AM Y PM | O46: AM Y PM | P46: AM Y PM | Q46: AM Y PM | R46: AM | S46: NO ASISTE | T46: AM Y PM | U46: AM Y PM | V46: AM Y PM | W46: AM Y PM | X46: AM Y PM | Y46: AM | Z46: NO ASISTE | AA46: AM Y PM | AB46: AM Y PM | AC46: AM Y PM | AD46: AM Y PM | AE46: AM Y PM | AF46: AM

Sheet AD_tis
B1: O1 | C1: O2 | D1: O3 | E1: O4 | F1: O5 | G1: O6 | H1: O7 | I1: O8 | J1: O9 | K1: O10 | L1: O11 | M1: O12 | N1: O13 | O1: O14 | P1: O15 | Q1: O16 | R1: O17 | S1: OP1 | T1: OP2 | U1: OP3 | V1: OP4 | W1: OP5 | X1: OP6 | Y1: OP7 | Z1: OP8 | AA1: OP9 | AB1: OP10 | AC1: E1 | AD1: E2 | AE1: E3 | AF1: E4 | AG1: E5 | AH1: E6 | AI1: E7 | AJ1: E8 | AK1: E9 | AL1: E10 | AM1: E11 | AN1: C1 | AO1: C2 | AP1: C3 | AQ1: C4 | AR1: C5 | AS1: C6 | AT1: C7 | AU1: C8 | AV1: C9 | AW1: L1 | AX1: L2 | AY1: S1 | AZ1: S2 | BA1: U1 | BB1: U2 | BC1: U3 | BD1: Sede1 | BE1: Sede2 | BF1: Sede3 | BG1: Sede4
A2: T1 | B2: 0 | C2: 0 | D2: 0 | E2: 1 | F2: 0 | G2: 0 | H2: 0 | I2: 0 | J2: 1 | K2: 0 | L2: 1 | M2: 1 | N2: 1 | O2: 0 | P2: 0 | Q2: 0 | R2: 1 | S2: 0 | T2: 0 | U2: 0 | V2: 0 | W2: 0 | X2: 0 | Y2: 0 | Z2: 0 | AA2: 0 | AB2: 0 | AC2: 0 | AD2: 0 | AE2: 0 | AF2: 0 | AG2: 0 | AH2: 0 | AI2: 0 | AJ2: 0 | AK2: 0 | AL2: 0 | AM2: 0 | AN2: 0 | AO2: 0 | AP2: 1 | AQ2: 0 | AR2: 0 | AS2: 0 | AT2: 0 | AU2: 0 | AV2: 0 | AW2: 0 | AX2: 1 | AY2: 0 | AZ2: 0 | BA2: 0 | BB2: 1 | BC2: 0 | BD2: =+Habilidad!B2 -> 1 | BE2: =+Habilidad!C2 -> 1 | BF2: =+Habilidad!D2 -> 1 | BG2: =+Habilidad!E2 -> 0
A3: T2 | B3: 0 | C3: 0 | D3: 0 | E3: 1 | F3: 0 | G3: 1 | H3: 0 | I3: 0 | J3: 1 | K3: 0 | L3: 1 | M3: 1 | N3: 1 | O3: 0 | P3: 0 | Q3: 1 | R3: 1 | S3: 0 | T3: 0 | U3: 0 | V3: 0 | W3: 0 | X3: 0 | Y3: 0 | Z3: 0 | AA3: 0 | AB3: 0 | AC3: 0 | AD3: 0 | AE3: 0 | AF3: 0 | AG3: 0 | AH3: 0 | AI3: 0 | AJ3: 0 | AK3: 0 | AL3: 0 | AM3: 0 | AN3: 0 | AO3: 0 | AP3: 1 | AQ3: 0 | AR3: 0 | AS3: 0 | AT3: 0 | AU3: 0 | AV3: 0 | AW3: 0 | AX3: 1 | AY3: 0 | AZ3: 0 | BA3: 0 | BB3: 0 | BC3: 0 | BD3: =+Habilidad!B3 -> 1 | BE3: =+Habilidad!C3 -> 1 | BF3: =+Habilidad!D3 -> 1 | BG3: =+Habilidad!E3 -> 0
A4: T3 | B4: 0 | C4: 0 | D4: 0 | E4: 1 | F4: 0 | G4: 1 | H4: 0 | I4: 0 | J4: 1 | K4: 0 | L4: 1 | M4: 1 | N4: 1 | O4: 0 | P4: 0 | Q4: 1 | R4: 1 | S4: 0 | T4: 0 | U4: 0 | V4: 0 | W4: 0 | X4: 0 | Y4: 0 | Z4: 0 | AA4: 0 | AB4: 0 | AC4: 0 | AD4: 0 | AE4: 0 | AF4: 0 | AG4: 0 | AH4: 0 | AI4: 0 | AJ4: 0 | AK4: 0 | AL4: 1 | AM4: 0 | AN4: 0 | AO4: 0 | AP4: 1 | AQ4: 1 | AR4: 0 | AS4: 0 | AT4: 0 | AU4: 0 | AV4: 0 | AW4: 0 | AX4: 1 | AY4: 0 | AZ4: 0 | BA4: 0 | BB4: 0 | BC4: 0 | BD4: =+Habilidad!B4 -> 1 | BE4: =+Habilidad!C4 -> 1 | BF4: =+Habilidad!D4 -> 1 | BG4: =+Habilidad!E4 -> 1
A5: T4 | B5: 0 | C5: 0 | D5: 0 | E5: 1 | F5: 0 | G5: 1 | H5: 0 | I5: 0 | J5: 1 | K5: 0 | L5: 1 | M5: 1 | N5: 1 | O5: 0 | P5: 0 | Q5: 1 | R5: 1 | S5: 0 | T5: 0 | U5: 0 | V5: 0 | W5: 0 | X5: 0 | Y5: 0 | Z5: 0 | AA5: 0 | AB5: 0 | AC5: 0 | AD5: 0 | AE5: 0 | AF5: 0 | AG5: 0 | AH5: 0 | AI5: 0 | AJ5: 0 | AK5: 0 | AL5: 0 | AM5: 0 | AN5: 0 | AO5: 0 | AP5: 1 | AQ5: 1 | AR5: 0 | AS5: 0 | AT5: 0 | AU5: 0 | AV5: 0 | AW5: 0 | AX5: 1 | AY5: 0 | AZ5: 0 | BA5: 0 | BB5: 0 | BC5: 0 | BD5: =+Habilidad!B5 -> 1 | BE5: =+Habilidad!C5 -> 1 | BF5: =+Habilidad!D5 -> 1 | BG5: =+Habilidad!E5 -> 0
A6: T5 | B6: 0 | C6: 0 | D6: 1 | E6: 0 | F6: 0 | G6: 1 | H6: 0 | I6: 0 | J6: 1 | K6: 0 | L6: 1 | M6: 1 | N6: 1 | O6: 0 | P6: 0 | Q6: 0 | R6: 0 | S6: 0 | T6: 0 | U6: 0 | V6: 0 | W6: 0 | X6: 0 | Y6: 0 | Z6: 0 | AA6: 0 | AB6: 0 | AC6: 0 | AD6: 0 | AE6: 0 | AF6: 0 | AG6: 0 | AH6: 0 | AI6: 0 | AJ6: 0 | AK6: 0 | AL6: 0 | AM6: 0 | AN6: 1 | AO6: 0 | AP6: 0 | AQ6: 1 | AR6: 0 | AS6: 0 | AT6: 0 | AU6: 0 | AV6: 0 | AW6: 0 | AX6: 1 | AY6: 0 | AZ6: 1 | BA6: 0 | BB6: 0 | BC6: 0 | BD6: =+Habilidad!B6 -> 1 | BE6: =+Habilidad!C6 -> 1 | BF6: =+Habilidad!D6 -> 0 | BG6: =+Habilidad!E6 -> 1
A7: T6 | B7: 0 | C7: 0 | D7: 0 | E7: 0 | F7: 0 | G7: 1 | H7: 1 | I7: 1 | J7: 1 | K7: 0 | L7: 1 | M7: 1 | N7: 1 | O7: 0 | P7: 0 | Q7: 1 | R7: 1 | S7: 0 | T7: 0 | U7: 0 | V7: 0 | W7: 0 | X7: 0 | Y7: 0 | Z7: 0 | AA7: 0 | AB7: 0 | AC7: 0 | AD7: 0 | AE7: 0 | AF7: 0 | AG7: 0 | AH7: 0 | AI7: 0 | AJ7: 0 | AK7: 0 | AL7: 1 | AM7: 0 | AN7: 0 | AO7: 0 | AP7: 0 | AQ7: 1 | AR7: 0 | AS7: 0 | AT7: 0 | AU7: 0 | AV7: 0 | AW7: 0 | AX7: 1 | AY7: 0 | AZ7: 0 | BA7: 0 | BB7: 0 | BC7: 0 | BD7: =+Habilidad!B7 -> 1 | BE7: =+Habilidad!C7 -> 1 | BF7: =+Habilidad!D7 -> 1 | BG7: =+Habilidad!E7 -> 1
A8: T7 | B8: 0 | C8: 0 | D8: 0 | E8: 0 | F8: 0 | G8: 1 | H8: 0 | I8: 0 | J8: 1 | K8: 0 | L8: 1 | M8: 1 | N8: 1 | O8: 0 | P8: 0 | Q8: 1 | R8: 1 | S8: 0 | T8: 0 | U8: 0 | V8: 0 | W8: 0 | X8: 0 | Y8: 0 | Z8: 0 | AA8: 0 | AB8: 0 | AC8: 0 | AD8: 0 | AE8: 0 | AF8: 0 | AG8: 0 | AH8: 0 | AI8: 0 | AJ8: 0 | AK8: 0 | AL8: 0 | AM8: 0 | AN8: 0 | AO8: 0 | AP8: 0 | AQ8: 1 | AR8: 0 | AS8: 0 | AT8: 0 | AU8: 0 | AV8: 0 | AW8: 0 | AX8: 1 | AY8: 0 | AZ8: 0 | BA8: 0 | BB8: 1 | BC8: 0 | BD8: =+Habilidad!B8 -> 1 | BE8: =+Habilidad!C8 -> 1 | BF8: =+Habilidad!D8 -> 1 | BG8: =+Habilidad!E8 -> 0
A9: T8 | B9: 0 | C9: 0 | D9: 0 | E9: 1 | F9: 0 | G9: 1 | H9: 0 | I9: 0 | J9: 1 | K9: 0 | L9: 1 | M9: 1 | N9: 1 | O9: 0 | P9: 0 | Q9: 1 | R9: 1 | S9: 0 | T9: 0 | U9: 0 | V9: 0 | W9: 0 | X9: 0 | Y9: 0 | Z9: 0 | AA9: 0 | AB9: 0 | AC9: 0 | AD9: 0 | AE9: 0 | AF9: 0 | AG9: 0 | AH9: 0 | AI9: 0 | AJ9: 0 | AK9: 0 | AL9: 1 | AM9: 0 | AN9: 0 | AO9: 0 | AP9: 0 | AQ9: 1 | AR9: 0 | AS9: 0 | AT9: 1 | AU9: 0 | AV9: 0 | AW9: 0 | AX9: 1 | AY9: 0 | AZ9: 0 | BA9: 0 | BB9: 1 | BC9: 0 | BD9: =+Habilidad!B9 -> 1 | BE9: =+Habilidad!C9 -> 1 | BF9: =+Habilidad!D9 -> 1 | BG9: =+Habilidad!E9 -> 0
A10: T9 | B10: 0 | C10: 0 | D10: 1 | E10: 0 | F10: 0 | G10: 1 | H10: 0 | I10: 0 | J10: 1 | K10: 0 | L10: 1 | M10: 1 | N10: 1 | O10: 0 | P10: 0 | Q10: 0 | R10: 1 | S10: 0 | T10: 0 | U10: 0 | V10: 0 | W10: 0 | X10: 0 | Y10: 0 | Z10: 0 | AA10: 0 | AB10: 0 | AC10: 0 | AD10: 0 | AE10: 0 | AF10: 0 | AG10: 0 | AH10: 0 | AI10: 0 | AJ10: 0 | AK10: 0 | AL10: 0 | AM10: 0 | AN10: 1 | AO10: 0 | AP10: 0 | AQ10: 1 | AR10: 0 | AS10: 0 | AT10: 0 | AU10: 0 | AV10: 0 | AW10: 0 | AX10: 0 | AY10: 0 | AZ10: 1 | BA10: 0 | BB10: 0 | BC10: 0 | BD10: =+Habilidad!B10 -> 1 | BE10: =+Habilidad!C10 -> 1 | BF10: =+Habilidad!D10 -> 0 | BG10: =+Habilidad!E10 -> 0
A11: T10 | B11: 0 | C11: 0 | D11: 0 | E11: 0 | F11: 1 | G11: 1 | H11: 0 | I11: 0 | J11: 1 | K11: 0 | L11: 0 | M11: 1 | N11: 1 | O11: 0 | P11: 0 | Q11: 0 | R11: 1 | S11: 0 | T11: 0 | U11: 0 | V11: 0 | W11: 0 | X11: 0 | Y11: 0 | Z11: 0 | AA11: 0 | AB11: 0 | AC11: 0 | AD11: 0 | AE11: 0 | AF11: 0 | AG11: 0 | AH11: 0 | AI11: 0 | AJ11: 0 | AK11: 0 | AL11: 0 | AM11: 0 | AN11: 0 | AO11: 1 | AP11: 0 | AQ11: 0 | AR11: 0 | AS11: 0 | AT11: 0 | AU11: 0 | AV11: 0 | AW11: 0 | AX11: 0 | AY11: 0 | AZ11: 0 | BA11: 0 | BB11: 0 | BC11: 0 | BD11: =+Habilidad!B11 -> 1 | BE11: =+Habilidad!C11 -> 1 | BF11: =+Habilidad!D11 -> 0 | BG11: =+Habilidad!E11 -> 1
A12: T11 | B12: 0 | C12: 0 | D12: 0 | E12: 0 | F12: 0 | G12: 1 | H12: 0 | I12: 0 | J12: 1 | K12: 0 | L12: 1 | M12: 1 | N12: 0 | O12: 0 | P12: 0 | Q12: 0 | R12: 0 | S12: 0 | T12: 0 | U12: 0 | V12: 0 | W12: 0 | X12: 0 | Y12: 0 | Z12: 0 | AA12: 0 | AB12: 0 | AC12: 0 | AD12: 0 | AE12: 0 | AF12: 0 | AG12: 0 | AH12: 0 | AI12: 0 | AJ12: 0 | AK12: 0 | AL12: 0 | AM12: 0 | AN12: 0 | AO12: 0 | AP12: 0 | AQ12: 0 | AR12: 0 | AS12: 0 | AT12: 0 | AU12: 0 | AV12: 0 | AW12: 0 | AX12: 0 | AY12: 0 | AZ12: 0 | BA12: 0 | BB12: 0 | BC12: 0 | BD12: =+Habilidad!B12 -> 1 | BE12: =+Habilidad!C12 -> 1 | BF12: =+Habilidad!D12 -> 1 | BG12: =+Habilidad!E12 -> 0
A13: T12 | B13: 0 | C13: 0 | D13: 0 | E13: 0 | F13: 1 | G13: 1 | H13: 0 | I13: 0 | J13: 1 | K13: 0 | L13: 0 | M13: 1 | N13: 1 | O13: 0 | P13: 0 | Q13: 0 | R13: 1 | S13: 0 | T13: 0 | U13: 0 | V13: 0 | W13: 0 | X13: 0 | Y13: 0 | Z13: 0 | AA13: 0 | AB13: 0 | AC13: 0 | AD13: 0 | AE13: 0 | AF13: 0 | AG13: 0 | AH13: 0 | AI13: 0 | AJ13: 0 | AK13: 0 | AL13: 0 | AM13: 0 | AN13: 0 | AO13: 1 | AP13: 0 | AQ13: 0 | AR13: 0 | AS13: 0 | AT13: 0 | AU13: 0 | AV13: 0 | AW13: 0 | AX13: 0 | AY13: 0 | AZ13: 0 | BA13: 0 | BB13: 0 | BC13: 0 | BD13: =+Habilidad!B13 -> 1 | BE13: =+Habilidad!C13 -> 1 | BF13: =+Habilidad!D13 -> 0 | BG13: =+Habilidad!E13 -> 1
... A29: T28 | B29: 0 | C29: 0 | D29: 0 | E29: 0 | F29: 0 | G29: 1 | H29: 0 | I29: 0 | J29: 1 | K29: 0 | L29: 0 | M29: 0 | N29: 0 | O29: 0 | P29: 0 | Q29: 0 | R29: 0 | S29: 0 | T29: 0 | U29: 0 | V29: 0 | W29: 0 | X29: 0 | Y29: 0 | Z29: 0 | AA29: 0 | AB29: 0 | AC29: 0 | AD29: 0 | AE29: 0 | AF29: 0 | AG29: 0 | AH29: 0 | AI29: 0 | AJ29: 0 | AK29: 0 | AL29: 0 | AM29: 0 | AN29: 0 | AO29: 0 | AP29: 0 | AQ29: 0 | AR29: 0 | AS29: 0 | AT29: 0 | AU29: 0 | AV29: 0 | AW29: 0 | AX29: 0 | AY29: 0 | AZ29: 0 | BA29: 0 | BB29: 0 | BC29: 0 | BD29: =+Habilidad!B29 -> 1 | BE29: =+Habilidad!C29 -> 1 | BF29: =+Habilidad!D29 -> 1 | BG29: =+Habilidad!E29 -> 0
A30: T29 | B30: 0 | C30: 0 | D30: 0 | E30: 0 | F30: 0 | G30: =+IF(J30=1,1,0) -> 0 | H30: 0 | I30: 0 | J30: 0 | K30: 0 | L30: 0 | M30: 0 | N30: 0 | O30: 0 | P30: 0 | Q30: 0 | R30: 0 | S30: 0 | T30: 0 | U30: 0 | V30: 0 | W30: 0 | X30: 0 | Y30: 0 | Z30: 0 | AA30: 0 | AB30: 0 | AC30: 0 | AD30: 0 | AE30: 0 | AF30: 0 | AG30: 0 | AH30: 0 | AI30: 0 | AJ30: 0 | AK30: 0 | AL30: 0 | AM30: 0 | AN30: 0 | AO30: 0 | AP30: 0 | AQ30: 0 | AR30: 0 | AS30: 0 | AT30: 0 | AU30: 0 | AV30: 0 | AW30: 0 | AX30: 0 | AY30: 0 | AZ30: 0 | BA30: 1 | BB30: 0 | BC30: 0 | BD30: =+Habilidad!B30 -> 1 | BE30: =+Habilidad!C30 -> 0 | BF30: =+Habilidad!D30 -> 0 | BG30: =+Habilidad!E30 -> 0
A31: T30 | B31: 0 | C31: 0 | D31: 0 | E31: 0 | F31: 0 | G31: =+IF(J31=1,1,0) -> 0 | H31: 0 | I31: 0 | J31: 0 | K31: 0 | L31: 0 | M31: 0 | N31: 0 | O31: 0 | P31: 0 | Q31: 0 | R31: 0 | S31: 0 | T31: 0 | U31: 0 | V31: 0 | W31: 0 | X31: 0 | Y31: 0 | Z31: 0 | AA31: 0 | AB31: 0 | AC31: 0 | AD31: 0 | AE31: 0 | AF31: 1 | AG31: 1 | AH31: 1 | AI31: 1 | AJ31: 1 | AK31: 1 | AL31: 0 | AM31: 0 | AN31: 0 | AO31: 0 | AP31: 0 | AQ31: 0 | AR31: 0 | AS31: 0 | AT31: 0 | AU31: 0 | AV31: 0 | AW31: 0 | AX31: 0 | AY31: 0 | AZ31: 0 | BA31: 0 | BB31: 0 | BC31: 0 | BD31: =+Habilidad!B31 -> 1 | BE31: =+Habilidad!C31 -> 0 | BF31: =+Habilidad!D31 -> 0 | BG31: =+Habilidad!E31 -> 0
A32: T31 | B32: 0 | C32: 0 | D32: 0 | E32: 0 | F32: 0 | G32: =+IF(J32=1,1,0) -> 0 | H32: 0 | I32: 0 | J32: 0 | K32: 0 | L32: 0 | M32: 0 | N32: 0 | O32: 0 | P32: 0 | Q32: 0 | R32: 0 | S32: 0 | T32: 0 | U32: 0 | V32: 0 | W32: 0 | X32: 0 | Y32: 0 | Z32: 0 | AA32: 0 | AB32: 0 | AC32: 1 | AD32: 1 | AE32: 1 | AF32: 1 | AG32: 1 | AH32: 1 | AI32: 1 | AJ32: 1 | AK32: 1 | AL32: 0 | AM32: 0 | AN32: 0 | AO32: 0 | AP32: 0 | AQ32: 0 | AR32: 0 | AS32: 0 | AT32: 0 | AU32: 0 | AV32: 0 | AW32: 0 | AX32: 0 | AY32: 0 | AZ32: 0 | BA32: 0 | BB32: 0 | BC32: 0 | BD32: =+Habilidad!B32 -> 1 | BE32: =+Habilidad!C32 -> 0 | BF32: =+Habilidad!D32 -> 0 | BG32: =+Habilidad!E32 -> 0
A33: T32 | B33: 0 | C33: 0 | D33: 0 | E33: 0 | F33: 0 | G33: =+IF(J33=1,1,0) -> 0 | H33: 0 | I33: 0 | J33: 0 | K33: 0 | L33: 0 | M33: 0 | N33: 0 | O33: 0 | P33: 0 | Q33: 0 | R33: 0 | S33: 0 | T33: 0 | U33: 0 | V33: 0 | W33: 0 | X33: 0 | Y33: 0 | Z33: 0 | AA33: 0 | AB33: 0 | AC33: 1 | AD33: 0 | AE33: 0 | AF33: 1 | AG33: 1 | AH33: 1 | AI33: 1 | AJ33: 1 | AK33: 1 | AL33: 0 | AM33: 0 | AN33: 0 | AO33: 0 | AP33: 0 | AQ33: 0 | AR33: 0 | AS33: 0 | AT33: 0 | AU33: 0 | AV33: 0 | AW33: 0 | AX33: 0 | AY33: 0 | AZ33: 0 | BA33: 0 | BB33: 0 | BC33: 0 | BD33: =+Habilidad!B33 -> 1 | BE33: =+Habilidad!C33 -> 0 | BF33: =+Habilidad!D33 -> 0 | BG33: =+Habilidad!E33 -> 0
A34: T33 | B34: 0 | C34: 0 | D34: 0 | E34: 0 | F34: 0 | G34: =+IF(J34=1,1,0) -> 0 | H34: 0 | I34: 0 | J34: 0 | K34: 0 | L34: 0 | M34: 0 | N34: 0 | O34: 0 | P34: 0 | Q34: 0 | R34: 0 | S34: 0 | T34: 0 | U34: 1 | V34: 0 | W34: 0 | X34: 0 | Y34: 0 | Z34: 1 | AA34: 1 | AB34: 0 | AC34: 1 | AD34: 1 | AE34: 1 | AF34: 1 | AG34: 1 | AH34: 1 | AI34: 1 | AJ34: 0 | AK34: 1 | AL34: 0 | AM34: 0 | AN34: 0 | AO34: 0 | AP34: 0 | AQ34: 0 | AR34: 0 | AS34: 0 | AT34: 0 | AU34: 0 | AV34: 0 | AW34: 0 | AX34: 0 | AY34: 0 | AZ34: 0 | BA34: 0 | BB34: 0 | BC34: 0 | BD34: =+Habilidad!B34 -> 1 | BE34: =+Habilidad!C34 -> 1 | BF34: =+Habilidad!D34 -> 1 | BG34: =+Habilidad!E34 -> 0
A35: T34 | B35: 0 | C35: 0 | D35: 0 | E35: 0 | F35: 0 | G35: =+IF(J35=1,1,0) -> 0 | H35: 0 | I35: 0 | J35: 0 | K35: 1 | L35: 0 | M35: 0 | N35: 0 | O35: 0 | P35: 0 | Q35: 0 | R35: 0 | S35: 0 | T35: 0 | U35: 0 | V35: 0 | W35: 0 | X35: 0 | Y35: 0 | Z35: 0 | AA35: 1 | AB35: 0 | AC35: 0 | AD35: 0 | AE35: 0 | AF35: 0 | AG35: 1 | AH35: 0 | AI35: 0 | AJ35: 0 | AK35: 0 | AL35: 0 | AM35: 0 | AN35: 0 | AO35: 0 | AP35: 0 | AQ35: 0 | AR35: 0 | AS35: 0 | AT35: 0 | AU35: 0 | AV35: 0 | AW35: 0 | AX35: 0 | AY35: 0 | AZ35: 0 | BA35: 0 | BB35: 0 | BC35: 0 | BD35: =+Habilidad!B35 -> 1 | BE35: =+Habilidad!C35 -> 1 | BF35: =+Habilidad!D35 -> 1 | BG35: =+Habilidad!E35 -> 0
A36: T35 | B36: 0 | C36: 0 | D36: 0 | E36: 0 | F36: 0 | G36: =+IF(J36=1,1,0) -> 0 | H36: 0 | I36: 0 | J36: 0 | K36: 0 | L36: 0 | M36: 0 | N36: 0 | O36: 0 | P36: 0 | Q36: 0 | R36: 0 | S36: 0 | T36: 0 | U36: 0 | V36: 0 | W36: 0 | X36: 0 | Y36: 0 | Z36: 0 | AA36: 0 | AB36: 0 | AC36: 0 | AD36: 0 | AE36: 0 | AF36: 0 | AG36: 0 | AH36: 0 | AI36: 0 | AJ36: 0 | AK36: 0 | AL36: 0 | AM36: 0 | AN36: 0 | AO36: 0 | AP36: 0 | AQ36: 0 | AR36: 0 | AS36: 0 | AT36: 0 | AU36: 0 | AV36: 0 | AW36: 0 | AX36: 0 | AY36: 1 | AZ36: 0 | BA36: 0 | BB36: 0 | BC36: 0 | BD36: =+Habilidad!B36 -> 1 | BE36: =+Habilidad!C36 -> 1 | BF36: =+Habilidad!D36 -> 0 | BG36: =+Habilidad!E36 -> 0
A37: T36 | B37: 0 | C37: 0 | D37: 0 | E37: 0 | F37: 0 | G37: =+IF(J37=1,1,0) -> 0 | H37: 0 | I37: 0 | J37: 0 | K37: 0 | L37: 1 | M37: 1 | N37: 1 | O37: 0 | P37: 0 | Q37: 0 | R37: 0 | S37: 0 | T37: 0 | U37: 0 | V37: 0 | W37: 0 | X37: 0 | Y37: 0 | Z37: 0 | AA37: 0 | AB37: 0 | AC37: 0 | AD37: 0 | AE37: 0 | AF37: 0 | AG37: 0 | AH37: 0 | AI37: 0 | AJ37: 0 | AK37: 0 | AL37: 0 | AM37: 0 | AN37: 0 | AO37: 0 | AP37: 1 | AQ37: 0 | AR37: 0 | AS37: 0 | AT37: 0 | AU37: 0 | AV37: 0 | AW37: 0 | AX37: 0 | AY37: 0 | AZ37: 0 | BA37: 0 | BB37: 0 | BC37: 0 | BD37: =+Habilidad!B37 -> 1 | BE37: =+Habilidad!C37 -> 1 | BF37: =+Habilidad!D37 -> 0 | BG37: =+Habilidad!E37 -> 0
A38: T37 | B38: 0 | C38: 0 | D38: 0 | E38: 0 | F38: 0 | G38: =+IF(J38=1,1,0) -> 0 | H38: 0 | I38: 0 | J38: 0 | K38: 1 | L38: 0 | M38: 0 | N38: 0 | O38: 0 | P38: 0 | Q38: 0 | R38: 0 | S38: 0 | T38: 0 | U38: 1 | V38: 0 | W38: 0 | X38: 0 | Y38: 0 | Z38: 0 | AA38: 1 | AB38: 0 | AC38: 0 | AD38: 0 | AE38: 0 | AF38: 0 | AG38: 0 | AH38: 0 | AI38: 0 | AJ38: 0 | AK38: 0 | AL38: 0 | AM38: 1 | AN38: 0 | AO38: 0 | AP38: 0 | AQ38: 0 | AR38: 0 | AS38: 0 | AT38: 0 | AU38: 0 | AV38: 0 | AW38: 0 | AX38: 0 | AY38: 0 | AZ38: 0 | BA38: 0 | BB38: 0 | BC38: 0 | BD38: =+Habilidad!B38 -> 0 | BE38: =+Habilidad!C38 -> 0 | BF38: =+Habilidad!D38 -> 0 | BG38: =+Habilidad!E38 -> 1
A39: T38 | B39: 0 | C39: 0 | D39: 0 | E39: 0 | F39: 0 | G39: =+IF(J39=1,1,0) -> 0 | H39: 0 | I39: 0 | J39: 0 | K39: 1 | L39: 0 | M39: 0 | N39: 0 | O39: 0 | P39: 0 | Q39: 0 | R39: 0 | S39: 0 | T39: 0 | U39: 1 | V39: 0 | W39: 0 | X39: 0 | Y39: 0 | Z39: 0 | AA39: 1 | AB39: 0 | AC39: 0 | AD39: 0 | AE39: 0 | AF39: 0 | AG39: 0 | AH39: 0 | AI39: 0 | AJ39: 0 | AK39: 0 | AL39: 0 | AM39: 1 | AN39: 0 | AO39: 0 | AP39: 0 | AQ39: 0 | AR39: 0 | AS39: 0 | AT39: 0 | AU39: 0 | AV39: 0 | AW39: 0 | AX39: 0 | AY39: 0 | AZ39: 0 | BA39: 0 | BB39: 0 | BC39: 0 | BD39: =+Habilidad!B39 -> 0 | BE39: =+Habilidad!C39 -> 0 | BF39: =+Habilidad!D39 -> 0 | BG39: =+Habilidad!E39 -> 1
A40: T39 | B40: =+B10 -> 0 | C40: 0 | D40: 1 | E40: 0 | F40: 0 | G40: =+IF(J40=1,1,0) -> 1 | H40: 0 | I40: 0 | J40: 1 | K40: 0 | L40: 1 | M40: 1 | N40: 1 | O40: 0 | P40: 0 | Q40: 0 | R40: 1 | S40: 0 | T40: 0 | U40: 0 | V40: 0 | W40: 0 | X40: 0 | Y40: 0 | Z40: 0 | AA40: 0 | AB40: 0 | AC40: 0 | AD40: 0 | AE40: 0 | AF40: 0 | AG40: 0 | AH40: 0 | AI40: 0 | AJ40: 0 | AK40: 0 | AL40: 0 | AM40: 0 | AN40: 1 | AO40: 0 | AP40: 0 | AQ40: 1 | AR40: 0 | AS40: 0 | AT40: 0 | AU40: 0 | AV40: 0 | AW40: 0 | AX40: 0 | AY40: 0 | AZ40: 1 | BA40: 0 | BB40: 0 | BC40: 0 | BD40: =+Habilidad!B40 -> 1 | BE40: =+Habilidad!C40 -> 0 | BF40: =+Habilidad!D40 -> 0 | BG40: =+Habilidad!E40 -> 1
A41: T40 | B41: =+B23 -> 0 | C41: =+C23 -> 0 | D41: =+D23 -> 0 | E41: =+E23 -> 0 | F41: =+F23 -> 0 | G41: =+G23 -> 0 | H41: =+H23 -> 0 | I41: =+I23 -> 0 | ... AL41: =+AL23 -> 0 | AM41: 0 | AN41: =+AN23 -> 0 | AO41: =+AO23 -> 0 | AP41: =+AP23 -> 0 | AQ41: =+AQ23 -> 0 | AR41: =+AR23 -> 0 | AS41: =+AS23 -> 0 | AT41: =+AT23 -> 0 | AU41: =+AU23 -> 0 | ... AZ41: =+AZ23 -> 0 | BA41: 0 | BB41: =+BB23 -> 0 | BC41: =+BC23 -> 0 | BD41: =+Habilidad!B41 -> 1 | BE41: =+Habilidad!C41 -> 1 | BF41: =+Habilidad!D41 -> 1 | BG41: =+Habilidad!E41 -> 0
A42: T41 | B42: =+B22 -> 0 | C42: =+C22 -> 0 | D42: =+D22 -> 0 | E42: =+E22 -> 0 | F42: =+F22 -> 0 | G42: =+G22 -> 0 | H42: =+H22 -> 0 | I42: =+I22 -> 0 | ... AL42: =+AL22 -> 0 | AM42: 0 | AN42: =+AN22 -> 0 | AO42: =+AO22 -> 0 | AP42: =+AP22 -> 0 | AQ42: =+AQ22 -> 0 | AR42: =+AR22 -> 0 | AS42: =+AS22 -> 0 | AT42: =+AT22 -> 0 | AU42: =+AU22 -> 0 | ... AZ42: =+AZ22 -> 0 | BA42: 0 | BB42: =+BB22 -> 0 | BC42: =+BC22 -> 0 | BD42: =+Habilidad!B42 -> 0 | BE42: =+Habilidad!C42 -> 1 | BF42: =+Habilidad!D42 -> 0 | BG42: =+Habilidad!E42 -> 0
A43: T42 | B43: 0 | C43: 0 | D43: 0 | E43: 0 | F43: 0 | G43: =+IF(J43=1,1,0) -> 0 | H43: 0 | I43: 0 | J43: 0 | K43: 1 | L43: 0 | M43: 0 | N43: 0 | O43: 0 | P43: 0 | Q43: 0 | R43: 0 | S43: 0 | T43: 0 | U43: 0 | V43: 0 | W43: 0 | X43: 0 | Y43: 0 | Z43: 0 | AA43: 1 | AB43: 0 | AC43: 0 | AD43: 0 | AE43: 0 | AF43: 0 | AG43: 1 | AH43: 0 | AI43: 0 | AJ43: 0 | AK43: 0 | AL43: 0 | AM43: 0 | AN43: 0 | AO43: 0 | AP43: 0 | AQ43: 0 | AR43: 0 | AS43: 0 | AT43: 0 | AU43: 0 | AV43: 0 | AW43: 0 | AX43: 0 | AY43: 0 | AZ43: 0 | BA43: 0 | BB43: 0 | BC43: 0 | BD43: =+Habilidad!B43 -> 1 | BE43: =+Habilidad!C43 -> 1 | BF43: =+Habilidad!D43 -> 1 | BG43: =+Habilidad!E43 -> 0
A44: T43 | B44: 0 | C44: 0 | D44: 0 | E44: 0 | F44: 0 | G44: =+IF(J44=1,1,0) -> 0 | H44: 0 | I44: 0 | J44: 0 | K44: 1 | L44: 0 | M44: 0 | N44: 0 | O44: 0 | P44: 0 | Q44: 0 | R44: 0 | S44: 0 | T44: 0 | U44: 0 | V44: 0 | W44: 0 | X44: 0 | Y44: 0 | Z44: 0 | AA44: 1 | AB44: 0 | AC44: 0 | AD44: 0 | AE44: 0 | AF44: 0 | AG44: 1 | AH44: 0 | AI44: 0 | AJ44: 0 | AK44: 0 | AL44: 0 | AM44: 0 | AN44: 0 | AO44: 0 | AP44: 0 | AQ44: 0 | AR44: 0 | AS44: 0 | AT44: 0 | AU44: 0 | AV44: 0 | AW44: 0 | AX44: 0 | AY44: 0 | AZ44: 0 | BA44: 0 | BB44: 0 | BC44: 0 | BD44: =+Habilidad!B44 -> 1 | BE44: =+Habilidad!C44 -> 1 | BF44: =+Habilidad!D44 -> 1 | BG44: =+Habilidad!E44 -> 0
A45: T44 | B45: =+B15 -> 0 | C45: 0 | D45: 1 | E45: 0 | F45: 0 | G45: =+IF(J45=1,1,0) -> 1 | H45: 0 | I45: 0 | J45: 1 | K45: 0 | L45: 1 | M45: 1 | N45: 1 | O45: 0 | P45: 0 | Q45: 0 | R45: 1 | S45: 0 | T45: 0 | U45: 0 | V45: 0 | W45: 0 | X45: 0 | Y45: 0 | Z45: 0 | AA45: 0 | AB45: 0 | AC45: 0 | AD45: 0 | AE45: 0 | AF45: 0 | AG45: 0 | AH45: 0 | AI45: 0 | AJ45: 0 | AK45: 0 | AL45: 0 | AM45: 0 | AN45: 1 | AO45: 0 | AP45: 0 | AQ45: 1 | AR45: 0 | AS45: 0 | AT45: 0 | AU45: 0 | AV45: 0 | AW45: 0 | AX45: 0 | AY45: 0 | AZ45: 1 | BA45: 0 | BB45: 0 | BC45: 0 | BD45: =+Habilidad!B45 -> 1 | BE45: =+Habilidad!C45 -> 1 | BF45: =+Habilidad!D45 -> 1 | BG45: =+Habilidad!E45 -> 0
A46: T45 | B46: 0 | C46: 0 | D46: 0 | E46: 0 | F46: 0 | G46: =+IF(J46=1,1,0) -> 0 | H46: 0 | I46: 0 | J46: 0 | K46: 1 | L46: 0 | M46: 0 | N46: 0 | O46: 0 | P46: 0 | Q46: 0 | R46: 0 | S46: 0 | T46: 0 | U46: 0 | V46: 0 | W46: 0 | X46: 0 | Y46: 0 | Z46: 0 | AA46: 1 | AB46: 0 | AC46: 0 | AD46: 0 | AE46: 0 | AF46: 0 | AG46: 1 | AH46: 0 | AI46: 0 | AJ46: 0 | AK46: 0 | AL46: 0 | AM46: 0 | AN46: 0 | AO46: 0 | AP46: 0 | AQ46: 0 | AR46: 0 | AS46: 0 | AT46: 0 | AU46: 0 | AV46: 0 | AW46: 0 | AX46: 0 | AY46: 0 | AZ46: 0 | BA46: 0 | BB46: 0 | BC46: 0 | BD46: =+Habilidad!B46 -> 1 | BE46: =+Habilidad!C46 -> 1 | BF46: =+Habilidad!D46 -> 1 | BG46: =+Habilidad!E46 -> 0
A47: Sede 1 | B47: =+K_si!B2 -> 1 | C47: =+K_si!C2 -> 1 | D47: =+K_si!D2 -> 1 | E47: =+K_si!E2 -> 1 | F47: =+K_si!F2 -> 0 | G47: =+K_si!G2 -> 0 | H47: =+K_si!H2 -> 1 | I47: =+K_si!I2 -> 1 | ... BC47: =+K_si!BC2 -> 0
A48: Sede 2 | B48: =+K_si!B3 -> 0 | C48: =+K_si!C3 -> 0 | D48: =+K_si!D3 -> 0 | E48: =+K_si!E3 -> 0 | F48: =+K_si!F3 -> 1 | G48: =+K_si!G3 -> 1 | H48: =+K_si!H3 -> 0 | I48: =+K_si!I3 -> 0 | ... BC48: =+K_si!BC3 -> 0
A49: Sede 3 | B49: =+K_si!B4 -> 0 | C49: =+K_si!C4 -> 0 | D49: =+K_si!D4 -> 0 | E49: =+K_si!E4 -> 0 | F49: =+K_si!F4 -> 0 | G49: =+K_si!G4 -> 1 | H49: =+K_si!H4 -> 0 | I49: =+K_si!I4 -> 0 | ... BC49: =+K_si!BC4 -> 0
A50: Sede 4 | B50: =+K_si!B5 -> 0 | C50: =+K_si!C5 -> 0 | D50: =+K_si!D5 -> 1 | E50: =+K_si!E5 -> 1 | F50: =+K_si!F5 -> 1 | G50: =+K_si!G5 -> 1 | H50: =+K_si!H5 -> 1 | I50: =+K_si!I5 -> 1 | ... BC50: =+K_si!BC5 -> 0
A51: Sede 5 | B51: =+K_si!B6 -> 0 | C51: =+K_si!C6 -> 0 | D51: =+K_si!D6 -> 0 | E51: =+K_si!E6 -> 0 | F51: =+K_si!F6 -> 0 | G51: =+K_si!G6 -> 0 | H51: =+K_si!H6 -> 0 | I51: =+K_si!I6 -> 0 | ... BC51: =+K_si!BC6 -> 1

Sheet DEMANDA
B1: O1 | C1: O2 | D1: O3 | E1: O4 | F1: O5 | G1: O6 | H1: O7 | I1: O8 | J1: O9 | K1: O10 | L1: O11 | M1: O12 | N1: O13 | O1: O14 | P1: O15 | Q1: O16 | R1: O17 | S1: OP1 | T1: OP2 | U1: OP3 | V1: OP4 | W1: OP5 | X1: OP6 | Y1: OP7 | Z1: OP8 | AA1: OP 9 | AB1: OP10 | AC1: E1 | AD1: E2 | AE1: E3 | AF1: E4 | AG1: E5 | AH1: E6 | AI1: E7 | AJ1: E8 | AK1: E9 | AL1: E10 | AM1: E11 | AN1: C1 | AO1: C2 | AP1: C3 | AQ1: C4 | AR1: C5 | AS1: C6 | AT1: C7 | AU1: C8 | AV1: C9 | AW1: L1 | AX1: L2 | AY1: S1 | AZ1: S2 | BA1: U1 | BB1: U2 | BC1: U3
A2: S1 | B2: 324 | C2: 291 | D2: 202 | E2: 205 | F2: 0 | G2: 0 | H2: 91 | I2: 94 | J2: 678 | K2: 0 | L2: 250 | M2: 190 | N2: 153 | O2: 60 | P2: 182 | Q2: 0 | R2: 1495 | S2: 0 | T2: 0 | U2: 1221 | V2: 0 | W2: 0 | X2: 0 | Y2: 44 | Z2: 1495 | AA2: 120 | AB2: 0 | AC2: 135 | AD2: 0 | AE2: 223 | AF2: 206 | AG2: 265 | AH2: 229 | AI2: 728 | AJ2: 78 | AK2: 19 | AL2: 172 | AM2: 0 | AN2: 46 | AO2: 6 | AP2: 174 | AQ2: 103 | AR2: 43 | AS2: 40 | AT2: 5 | AU2: 10 | AV2: 292 | AW2: 67 | AX2: 159 | AY2: 65 | AZ2: 10 | BA2: 0 | BB2: 0 | BC2: 0
A3: S2 | B3: 0 | C3: 0 | D3: 0 | E3: 0 | F3: 294 | G3: 1800 | H3: 0 | I3: 0 | J3: 0 | K3: =1800/2 -> 900 | L3: 0 | M3: 185 | N3: 0 | O3: 0 | P3: 0 | Q3: 883 | R3: 0 | S3: 0 | T3: 50 | U3: 1221 | V3: 184 | W3: 0 | X3: =146/2 -> 73 | Y3: 0 | Z3: 0 | AA3: 0 | AB3: 69 | AC3: 0 | AD3: 0 | AE3: 0 | AF3: 0 | AG3: 0 | AH3: 0 | AI3: 0 | AJ3: 0 | AK3: 0 | AL3: 0 | AM3: 0 | AN3: 0 | AO3: 0 | AP3: 0 | AQ3: 0 | AR3: 0 | AS3: 0 | AT3: 0 | AU3: 0 | AV3: 0 | AW3: 0 | AX3: 0 | AY3: 0 | AZ3: 0 | BA3: 0 | BB3: 0 | BC3: 0
A4: S3 | B4: 0 | C4: 0 | D4: 0 | E4: 0 | F4: 0 | G4: 935 | H4: 0 | I4: 0 | J4: 0 | K4: =935/2 -> 467.5 | L4: 0 | M4: 0 | N4: 0 | O4: 0 | P4: 0 | Q4: 0 | R4: 0 | S4: 0 | T4: 0 | U4: 244 | V4: 0 | W4: 0 | X4: 0 | Y4: 0 | Z4: 0 | AA4: 0 | AB4: 0 | AC4: 0 | AD4: 0 | AE4: 0 | AF4: 0 | AG4: 0 | AH4: 0 | AI4: 0 | AJ4: 0 | AK4: 0 | AL4: 0 | AM4: 0 | AN4: 0 | AO4: 0 | AP4: 0 | AQ4: 0 | AR4: 0 | AS4: 0 | AT4: 0 | AU4: 0 | AV4: 0 | AW4: 0 | AX4: 0 | AY4: 0 | AZ4: 0 | BA4: 0 | BB4: 0 | BC4: 0
A5: S4 | B5: 0 | C5: 0 | D5: 40 | E5: 40 | F5: 40 | G5: 620 | H5: 40 | I5: 81 | J5: 0 | K5: 620 | L5: 40 | M5: 40 | N5: 30 | O5: 0 | P5: 0 | Q5: 0 | R5: 0 | S5: 0 | T5: 0 | U5: 30 | V5: 0 | W5: 0 | X5: 0 | Y5: 0 | Z5: 0 | AA5: 0 | AB5: 0 | AC5: 0 | AD5: 20 | AE5: 30 | AF5: 0 | AG5: 0 | AH5: 0 | AI5: 0 | AJ5: 0 | AK5: 0 | AL5: 17 | AM5: 166 | AN5: 0 | AO5: 0 | AP5: 0 | AQ5: 0 | AR5: 0 | AS5: 0 | AT5: 0 | AU5: 0 | AV5: 0 | AW5: 0 | AX5: 0 | AY5: 0 | AZ5: 0 | BA5: 0 | BB5: 0 | BC5: 0
A6: S5 | B6: 0 | C6: 0 | D6: 0 | E6: 0 | F6: 0 | G6: 0 | H6: 0 | I6: 0 | J6: 0 | K6: 0 | L6: 0 | M6: 0 | N6: 0 | O6: 0 | P6: 0 | Q6: 0 | R6: 0 | S6: 0 | T6: 0 | U6: 0 | V6: 0 | W6: 0 | X6: 0 | Y6: 0 | Z6: 0 | AA6: 0 | AB6: 0 | AC6: 0 | AD6: 0 | AE6: 0 | AF6: 0 | AG6: 0 | AH6: 0 | AI6: 0 | AJ6: 0 | AK6: 0 | AL6: 0 | AM6: 0 | AN6: 0 | AO6: 0 | AP6: 0 | AQ6: 0 | AR6: 0 | AS6: 0 | AT6: 0 | AU6: 0 | AV6: 0 | AW6: 0 | AX6: 0 | AY6: 0 | AZ6: 0 | BA6: 80 | BB6: 80 | BC6: 80

Sheet D_si(2)
B1: O1 | C1: O2 | D1: O3 | E1: O4 | F1: O5 | G1: O6 | H1: O7 | I1: O8 | J1: O9 | K1: O10 | L1: O11 | M1: O12 | N1: O13 | O1: O14 | P1: O15 | Q1: O16 | R1: O17 | S1: OP1 | T1: OP2 | U1: OP3 | V1: OP4 | W1: OP5 | X1: OP6 | Y1: OP7 | Z1: OP8 | AA1: OP 9 | AB1: OP10 | AC1: E1 | AD1: E2 | AE1: E3 | AF1: E4 | AG1: E5 | AH1: E6 | AI1: E7 | AJ1: E8 | AK1: E9 | AL1: E10 | AM1: E11 | AN1: C1 | AO1: C2 | AP1: C3 | AQ1: C4 | AR1: C5 | AS1: C6 | AT1: C7 | AU1: C8 | AV1: C9 | AW1: L1 | AX1: L2 | AY1: S1 | AZ1: S2 | BA1: U1 | BB1: U2 | BC1: U3
A2: S1 | B2: =+DEMANDA!B2-DEMANDA!B2 -> 0 | C2: =+DEMANDA!C2-DEMANDA!C2 -> 0 | D2: =+DEMANDA!D2-DEMANDA!D2 -> 0 | E2: =+DEMANDA!E2-DEMANDA!E2 -> 0 | F2: =+DEMANDA!F2-DEMANDA!F2 -> 0 | G2: =+DEMANDA!G2-DEMANDA!G2 -> 0 | H2: =+DEMANDA!H2-DEMANDA!H2 -> 0 | I2: =+DEMANDA!I2-DEMANDA!I2 -> 0 | ... AM2: =+DEMANDA!AM2-DEMANDA!AM2 -> 0 | AN2: =+DEMANDA!AN2 -> 46 | AO2: =+DEMANDA!AO2 -> 6 | AP2: =+DEMANDA!AP2 -> 174 | AQ2: =+DEMANDA!AQ2 -> 103 | AR2: =+DEMANDA!AR2 -> 43 | AS2: =+DEMANDA!AS2 -> 40 | AT2: =+DEMANDA!AT2 -> 5 | AU2: =+DEMANDA!AU2 -> 10 | AV2: =+DEMANDA!AV2 -> 292 | AW2: =+DEMANDA!AW2-DEMANDA!AW2 -> 0 | AX2: =+DEMANDA!AX2-DEMANDA!AX2 -> 0 | AY2: =+DEMANDA!AY2-DEMANDA!AY2 -> 0 | AZ2: =+DEMANDA!AZ2-DEMANDA!AZ2 -> 0 | BA2: =+DEMANDA!BA2-DEMANDA!BA2 -> 0 | BB2: =+DEMANDA!BB2-DEMANDA!BB2 -> 0 | BC2: =+DEMANDA!BC2-DEMANDA!BC2 -> 0
A3: S2 | B3: =+DEMANDA!B3-DEMANDA!B3 -> 0 | C3: =+DEMANDA!C3-DEMANDA!C3 -> 0 | D3: =+DEMANDA!D3-DEMANDA!D3 -> 0 | E3: =+DEMANDA!E3-DEMANDA!E3 -> 0 | F3: =+DEMANDA!F3-DEMANDA!F3 -> 0 | G3: =+DEMANDA!G3-DEMANDA!G3 -> 0 | H3: =+DEMANDA!H3-DEMANDA!H3 -> 0 | I3: =+DEMANDA!I3-DEMANDA!I3 -> 0 | ... BC3: =+DEMANDA!BC3-DEMANDA!BC3 -> 0
A4: S3 | B4: =+DEMANDA!B4-DEMANDA!B4 -> 0 | C4: =+DEMANDA!C4-DEMANDA!C4 -> 0 | D4: =+DEMANDA!D4-DEMANDA!D4 -> 0 | E4: =+DEMANDA!E4-DEMANDA!E4 -> 0 | F4: =+DEMANDA!F4-DEMANDA!F4 -> 0 | G4: =+DEMANDA!G4-DEMANDA!G4 -> 0 | H4: =+DEMANDA!H4-DEMANDA!H4 -> 0 | I4: =+DEMANDA!I4-DEMANDA!I4 -> 0 | ... BC4: =+DEMANDA!BC4-DEMANDA!BC4 -> 0
A5: S4 | B5: =+DEMANDA!B5-DEMANDA!B5 -> 0 | C5: =+DEMANDA!C5-DEMANDA!C5 -> 0 | D5: =+DEMANDA!D5-DEMANDA!D5 -> 0 | E5: =+DEMANDA!E5-DEMANDA!E5 -> 0 | F5: =+DEMANDA!F5-DEMANDA!F5 -> 0 | G5: =+DEMANDA!G5-DEMANDA!G5 -> 0 | H5: =+DEMANDA!H5-DEMANDA!H5 -> 0 | I5: =+DEMANDA!I5-DEMANDA!I5 -> 0 | ... BC5: =+DEMANDA!BC5-DEMANDA!BC5 -> 0
A6: S5 | B6: =+DEMANDA!B6-DEMANDA!B6 -> 0 | C6: =+DEMANDA!C6-DEMANDA!C6 -> 0 | D6: =+DEMANDA!D6-DEMANDA!D6 -> 0 | E6: =+DEMANDA!E6-DEMANDA!E6 -> 0 | F6: =+DEMANDA!F6-DEMANDA!F6 -> 0 | G6: =+DEMANDA!G6-DEMANDA!G6 -> 0 | H6: =+DEMANDA!H6-DEMANDA!H6 -> 0 | I6: =+DEMANDA!I6-DEMANDA!I6 -> 0 | ... BC6: =+DEMANDA!BC6-DEMANDA!BC6 -> 0

Sheet D_si
B1: O1 | C1: O2 | D1: O3 | E1: O4 | F1: O5 | G1: O6 | H1: O7 | I1: O8 | J1: O9 | K1: O10 | L1: O11 | M1: O12 | N1: O13 | O1: O14 | P1: O15 | Q1: O16 | R1: O17 | S1: OP1 | T1: OP2 | U1: OP3 | V1: OP4 | W1: OP5 | X1: OP6 | Y1: OP7 | Z1: OP8 | AA1: OP 9 | AB1: OP10 | AC1: E1 | AD1: E2 | AE1: E3 | AF1: E4 | AG1: E5 | AH1: E6 | AI1: E7 | AJ1: E8 | AK1: E9 | AL1: E10 | AM1: E11 | AN1: C1 | AO1: C2 | AP1: C3 | AQ1: C4 | AR1: C5 | AS1: C6 | AT1: C7 | AU1: C8 | AV1: C9 | AW1: L1 | AX1: L2 | AY1: S1 | AZ1: S2 | BA1: U1 | BB1: U2 | BC1: U3
A2: S1 | B2: =+DEMANDA!B2 -> 324 | C2: =+DEMANDA!C2 -> 291 | D2: =+DEMANDA!D2 -> 202 | E2: =+DEMANDA!E2 -> 205 | F2: =+DEMANDA!F2 -> 0 | G2: =+DEMANDA!G2 -> 0 | H2: =+DEMANDA!H2 -> 91 | I2: =+DEMANDA!I2 -> 94 | ... AM2: =+DEMANDA!AM2 -> 0 | AN2: =+DEMANDA!AN2-DEMANDA!AN2 -> 0 | AO2: =+DEMANDA!AO2-DEMANDA!AO2 -> 0 | AP2: =+DEMANDA!AP2-DEMANDA!AP2 -> 0 | AQ2: =+DEMANDA!AQ2-DEMANDA!AQ2 -> 0 | AR2: =+DEMANDA!AR2-DEMANDA!AR2 -> 0 | AS2: =+DEMANDA!AS2-DEMANDA!AS2 -> 0 | AT2: =+DEMANDA!AT2-DEMANDA!AT2 -> 0 | AU2: =+DEMANDA!AU2-DEMANDA!AU2 -> 0 | AV2: =+DEMANDA!AV2-DEMANDA!AV2 -> 0 | AW2: =+DEMANDA!AW2 -> 67 | AX2: =+DEMANDA!AX2 -> 159 | AY2: =+DEMANDA!AY2 -> 65 | AZ2: =+DEMANDA!AZ2 -> 10 | BA2: =+DEMANDA!BA2 -> 0 | BB2: =+DEMANDA!BB2 -> 0 | BC2: =+DEMANDA!BC2 -> 0
A3: S2 | B3: =+DEMANDA!B3 -> 0 | C3: =+DEMANDA!C3 -> 0 | D3: =+DEMANDA!D3 -> 0 | E3: =+DEMANDA!E3 -> 0 | F3: =+DEMANDA!F3 -> 294 | G3: =+DEMANDA!G3 -> 1800 | H3: =+DEMANDA!H3 -> 0 | I3: =+DEMANDA!I3 -> 0 | ... BC3: =+DEMANDA!BC3 -> 0
A4: S3 | B4: =+DEMANDA!B4 -> 0 | C4: =+DEMANDA!C4 -> 0 | D4: =+DEMANDA!D4 -> 0 | E4: =+DEMANDA!E4 -> 0 | F4: =+DEMANDA!F4 -> 0 | G4: =+DEMANDA!G4 -> 935 | H4: =+DEMANDA!H4 -> 0 | I4: =+DEMANDA!I4 -> 0 | ... BC4: =+DEMANDA!BC4 -> 0
A5: S4 | B5: =+DEMANDA!B5 -> 0 | C5: =+DEMANDA!C5 -> 0 | D5: =+DEMANDA!D5 -> 40 | E5: =+DEMANDA!E5 -> 40 | F5: =+DEMANDA!F5 -> 40 | G5: =+DEMANDA!G5 -> 620 | H5: =+DEMANDA!H5 -> 40 | I5: =+DEMANDA!I5 -> 81 | ... BC5: =+DEMANDA!BC5 -> 0
A6: S5 | B6: =+DEMANDA!B6 -> 0 | C6: =+DEMANDA!C6 -> 0 | D6: =+DEMANDA!D6 -> 0 | E6: =+DEMANDA!E6 -> 0 | F6: =+DEMANDA!F6 -> 0 | G6: =+DEMANDA!G6 -> 0 | H6: =+DEMANDA!H6 -> 0 | I6: =+DEMANDA!I6 -> 0 | ... BC6: =+DEMANDA!BC6 -> 80

Sheet K_si
B1: O1 | C1: O2 | D1: O3 | E1: O4 | F1: O5 | G1: O6 | H1: O7 | I1: O8 | J1: O9 | K1: O10 | L1: O11 | M1: O12 | N1: O13 | O1: O14 | P1: O15 | Q1: O16 | R1: O17 | S1: OP1 | T1: OP2 | U1: OP3 | V1: OP4 | W1: OP5 | X1: OP6 | Y1: OP7 | Z1: OP8 | AA1: OP 9 | AB1: OP10 | AC1: E1 | AD1: E2 | AE1: E3 | AF1: E4 | AG1: E5 | AH1: E6 | AI1: E7 | AJ1: E8 | AK1: E9 | AL1: E10 | AM1: E11 | AN1: C1 | AO1: C2 | AP1: C3 | AQ1: C4 | AR1: C5 | AS1: C6 | AT1: C7 | AU1: C8 | AV1: C9 | AW1: L1 | AX1: L2 | AY1: S1 | AZ1: S2 | BA1: U1 | BB1: U2 | BC1: U3
A2: S1 | B2: =+IF(DEMANDA!B2>=1,1,0) -> 1 | C2: =+IF(DEMANDA!C2>=1,1,0) -> 1 | D2: =+IF(DEMANDA!D2>=1,1,0) -> 1 | E2: =+IF(DEMANDA!E2>=1,1,0) -> 1 | F2: =+IF(DEMANDA!F2>=1,1,0) -> 0 | G2: =+IF(DEMANDA!G2>=1,1,0) -> 0 | H2: =+IF(DEMANDA!H2>=1,1,0) -> 1 | I2: =+IF(DEMANDA!I2>=1,1,0) -> 1 | ... BC2: =+IF(DEMANDA!BC2>=1,1,0) -> 0
A3: S2 | B3: =+IF(DEMANDA!B3>=1,1,0) -> 0 | C3: =+IF(DEMANDA!C3>=1,1,0) -> 0 | D3: =+IF(DEMANDA!D3>=1,1,0) -> 0 | E3: =+IF(DEMANDA!E3>=1,1,0) -> 0 | F3: =+IF(DEMANDA!F3>=1,1,0) -> 1 | G3: =+IF(DEMANDA!G3>=1,1,0) -> 1 | H3: =+IF(DEMANDA!H3>=1,1,0) -> 0 | I3: =+IF(DEMANDA!I3>=1,1,0) -> 0 | ... BC3: =+IF(DEMANDA!BC3>=1,1,0) -> 0
A4: S3 | B4: =+IF(DEMANDA!B4>=1,1,0) -> 0 | C4: =+IF(DEMANDA!C4>=1,1,0) -> 0 | D4: =+IF(DEMANDA!D4>=1,1,0) -> 0 | E4: =+IF(DEMANDA!E4>=1,1,0) -> 0 | F4: =+IF(DEMANDA!F4>=1,1,0) -> 0 | G4: =+IF(DEMANDA!G4>=1,1,0) -> 1 | H4: =+IF(DEMANDA!H4>=1,1,0) -> 0 | I4: =+IF(DEMANDA!I4>=1,1,0) -> 0 | ... BC4: =+IF(DEMANDA!BC4>=1,1,0) -> 0
A5: S4 | B5: =+IF(DEMANDA!B5>=1,1,0) -> 0 | C5: =+IF(DEMANDA!C5>=1,1,0) -> 0 | D5: =+IF(DEMANDA!D5>=1,1,0) -> 1 | E5: =+IF(DEMANDA!E5>=1,1,0) -> 1 | F5: =+IF(DEMANDA!F5>=1,1,0) -> 1 | G5: =+IF(DEMANDA!G5>=1,1,0) -> 1 | H5: =+IF(DEMANDA!H5>=1,1,0) -> 1 | I5: =+IF(DEMANDA!I5>=1,1,0) -> 1 | ... BC5: =+IF(DEMANDA!BC5>=1,1,0) -> 0
A6: S5 | B6: =+IF(DEMANDA!B6>=1,1,0) -> 0 | C6: =+IF(DEMANDA!C6>=1,1,0) -> 0 | D6: =+IF(DEMANDA!D6>=1,1,0) -> 0 | E6: =+IF(DEMANDA!E6>=1,1,0) -> 0 | F6: =+IF(DEMANDA!F6>=1,1,0) -> 0 | G6: =+IF(DEMANDA!G6>=1,1,0) -> 0 | H6: =+IF(DEMANDA!H6>=1,1,0) -> 0 | I6: =+IF(DEMANDA!I6>=1,1,0) -> 0 | ... BC6: =+IF(DEMANDA!BC6>=1,1,0) -> 1

Sheet Costo
B1: O1 | C1: O2 | D1: O3 | E1: O4 | F1: O5 | G1: O6 | H1: O7 | I1: O8 | J1: O9 | K1: O10 | L1: O11 | M1: O12 | N1: O13 | O1: O14 | P1: O15 | Q1: O16 | R1: O17 | S1: OP1 | T1: OP2 | U1: OP3 | V1: OP4 | W1: OP5 | X1: OP6 | Y1: OP7 | Z1: OP8 | AA1: OP 9 | AB1: OP10 | AC1: E1 | AD1: E2 | AE1: E3 | AF1: E4 | AG1: E5 | AH1: E6 | AI1: E7 | AJ1: E8 | AK1: E9 | AL1: E10 | AM1: E11 | AN1: C1 | AO1: C2 | AP1: C3 | AQ1: C4 | AR1: C5 | AS1: C6 | AT1: C7 | AU1: C8 | AV1: C9 | AW1: L1 | AX1: L2 | AY1: S1 | AZ1: S2 | BA1: U1 | BB1: U2 | BC1: U3
A2: S1 | B2: =+IF(D_si!B2>0,1,10000) -> 1 | C2: =+IF(D_si!C2>0,1,10000) -> 1 | D2: =+IF(D_si!D2>0,1,10000) -> 1 | E2: =+IF(D_si!E2>0,1,10000) -> 1 | F2: =+IF(D_si!F2>0,1,10000) -> 10000 | G2: =+IF(D_si!G2>0,1,10000) -> 10000 | H2: =+IF(D_si!H2>0,1,10000) -> 1 | I2: =+IF(D_si!I2>0,1,10000) -> 1 | ... BC2: =+IF(D_si!BC2>0,1,10000) -> 10000
A3: S2 | B3: =+IF(D_si!B3>0,1,10000) -> 10000 | C3: =+IF(D_si!C3>0,1,10000) -> 10000 | D3: =+IF(D_si!D3>0,1,10000) -> 10000 | E3: =+IF(D_si!E3>0,1,10000) -> 10000 | F3: =+IF(D_si!F3>0,1,10000) -> 1 | G3: =+IF(D_si!G3>0,1,10000) -> 1 | H3: =+IF(D_si!H3>0,1,10000) -> 10000 | I3: =+IF(D_si!I3>0,1,10000) -> 10000 | ... BC3: =+IF(D_si!BC3>0,1,10000) -> 10000
A4: S3 | B4: =+IF(D_si!B4>0,20,10000) -> 10000 | C4: =+IF(D_si!C4>0,20,10000) -> 10000 | D4: =+IF(D_si!D4>0,20,10000) -> 10000 | E4: =+IF(D_si!E4>0,20,10000) -> 10000 | F4: =+IF(D_si!F4>0,20,10000) -> 10000 | G4: =+IF(D_si!G4>0,20,10000) -> 20 | H4: =+IF(D_si!H4>0,20,10000) -> 10000 | I4: =+IF(D_si!I4>0,20,10000) -> 10000 | ... BC4: =+IF(D_si!BC4>0,20,10000) -> 10000
A5: S4 | B5: =+IF(D_si!B5>0,1,10000) -> 10000 | C5: =+IF(D_si!C5>0,1,10000) -> 10000 | D5: =+IF(D_si!D5>0,1,10000) -> 1 | E5: =+IF(D_si!E5>0,1,10000) -> 1 | F5: =+IF(D_si!F5>0,1,10000) -> 1 | G5: =+IF(D_si!G5>0,1,10000) -> 1 | H5: =+IF(D_si!H5>0,1,10000) -> 1 | I5: =+IF(D_si!I5>0,1,10000) -> 1 | ... BC5: =+IF(D_si!BC5>0,1,10000) -> 10000
A6: S5 | B6: =+IF(D_si!B6>0,1,10000) -> 10000 | C6: =+IF(D_si!C6>0,1,10000) -> 10000 | D6: =+IF(D_si!D6>0,1,10000) -> 10000 | E6: =+IF(D_si!E6>0,1,10000) -> 10000 | F6: =+IF(D_si!F6>0,1,10000) -> 10000 | G6: =+IF(D_si!G6>0,1,10000) -> 10000 | H6: =+IF(D_si!H6>0,1,10000) -> 10000 | I6: =+IF(D_si!I6>0,1,10000) -> 10000 | ... BC6: =+IF(D_si!BC6>0,1,10000) -> 1

Sheet CON_HAB
A1: SEDE 1 | B1: O1 | C1: O2 | D1: O3 | E1: O4 | F1: O5 | G1: O6 | H1: O7 | I1: O8 | J1: O9 | K1: O10 | L1: O11 | M1: O12 | N1: O13 | O1: O14 | P1: O15 | Q1: O16 | R1: O17 | S1: OP1 | T1: OP2 | U1: OP3 | V1: OP4 | W1: OP5 | X1: OP6 | Y1: OP 7 | Z1: OP8 | AA1: OP9 | AB1: OP10 | AC1: E1 | AD1: E2 | AE1: E3 | AF1: E4 | AG1: E5 | AH1: E6 | AI1: E7 | AJ1: E8 | AK1: E9 | AL1: E10 | AM1: E11 | AN1: C1 | AO1: C2 | AP1: C3 | AQ1: C4 | AR1: C5 | AS1: C6 | AT1: C7 | AU1: C8 | AV1: C9 | AW1: L1 | AX1: L2 | AY1: S1 | AZ1: S2 | BA1: E1 | BB1: E2 | BC1: E3
A2: C1 | B2: 1 | C2: 1 | D2: 1 | E2: 1 | F2: 1 | G2: 1 | H2: 1 | I2: 1 | J2: 1 | K2: 1 | L2: 1 | M2: 1 | N2: 1 | O2: 1 | P2: 1 | Q2: 0 | R2: 0 | S2: 0 | T2: 0 | U2: 0 | V2: 0 | W2: 0 | X2: 0 | Y2: 0 | Z2: 0 | AA2: 0 | AB2: 0 | AC2: 0 | AD2: 0 | AE2: 0 | AF2: 0 | AG2: 0 | AH2: 0 | AI2: 0 | AJ2: 0 | AK2: 0 | AL2: 0 | AM2: 0 | AN2: 0 | AO2: 0 | AP2: 0 | AQ2: 0 | AR2: 0 | AS2: 0 | AT2: 0 | AU2: 0 | AV2: 1 | AW2: 0 | AX2: 0 | AY2: 0 | AZ2: 0 | BA2: 1 | BB2: 0 | BC2: 0
A3: C2 | B3: =+B2 -> 1 | C3: =+C2 -> 1 | D3: =+D2 -> 1 | E3: =+E2 -> 1 | F3: =+F2 -> 1 | G3: =+G2 -> 1 | H3: =+H2 -> 1 | I3: =+I2 -> 1 | ... O3: =+O2 -> 1 | P3: 1 | Q3: 0 | R3: 0 | S3: =+S2 -> 0 | T3: =+T2 -> 0 | U3: =+U2 -> 0 | V3: =+V2 -> 0 | W3: =+W2 -> 0 | X3: =+X2 -> 0 | Y3: 0 | Z3: 0 | AA3: 0 | AB3: 0 | AC3: 0 | AD3: 0 | AE3: 0 | AF3: 0 | AG3: 0 | AH3: 0 | AI3: 0 | AJ3: 0 | AK3: 0 | AL3: 0 | AM3: 0 | AN3: 0 | AO3: 0 | AP3: 0 | AQ3: 0 | AR3: 0 | AS3: 0 | AT3: 0 | AU3: 0 | AV3: 1 | AW3: 0 | AX3: 0 | AY3: 0 | AZ3: 0 | BA3: 1 | BB3: 0 | BC3: 0
A4: C3 | B4: 1 | C4: =+C3 -> 1 | D4: =+D3 -> 1 | E4: =+E3 -> 1 | F4: =+F3 -> 1 | G4: =+G3 -> 1 | H4: =+H3 -> 1 | I4: =+I3 -> 1 | J4: =+J3 -> 1 | ... M4: =+M3 -> 1 | N4: 0 | O4: 0 | P4: 1 | Q4: 0 | R4: 0 | S4: =+S3 -> 0 | T4: =+T3 -> 0 | U4: =+U3 -> 0 | V4: =+V3 -> 0 | W4: =+W3 -> 0 | X4: =+X3 -> 0 | Y4: 0 | Z4: 0 | AA4: 0 | AB4: 0 | AC4: 0 | AD4: 0 | AE4: 0 | AF4: 0 | AG4: 0 | AH4: 0 | AI4: 0 | AJ4: 0 | AK4: 0 | AL4: 0 | AM4: 0 | AN4: 0 | AO4: 0 | AP4: 0 | AQ4: 0 | AR4: 0 | AS4: 0 | AT4: 0 | AU4: 0 | AV4: 1 | AW4: 0 | AX4: 0 | AY4: 0 | AZ4: 0 | BA4: 1 | BB4: 0 | BC4: 0
A5: C4 | B5: 0 | C5: 0 | D5: 0 | E5: 0 | F5: 0 | G5: 0 | H5: 0 | I5: 0 | J5: 0 | K5: 1 | L5: 0 | M5: 0 | N5: 0 | O5: 0 | P5: 1 | Q5: 0 | R5: 0 | S5: 1 | T5: 1 | U5: 1 | V5: 1 | W5: 0 | X5: 0 | Y5: 1 | Z5: 1 | AA5: 1 | AB5: 0 | AC5: 0 | AD5: 0 | AE5: 0 | AF5: 0 | AG5: 0 | AH5: 0 | AI5: 0 | AJ5: 0 | AK5: 0 | AL5: 0 | AM5: 0 | AN5: 0 | AO5: 0 | AP5: 0 | AQ5: 0 | AR5: 0 | AS5: 0 | AT5: 0 | AU5: 0 | AV5: 1 | AW5: 0 | AX5: 0 | AY5: 0 | AZ5: 0 | BA5: 0 | BB5: 0 | BC5: 0
A6: C5 | B6: 1 | C6: 1 | D6: 1 | E6: 1 | F6: 1 | G6: 1 | H6: 1 | I6: 1 | J6: 1 | K6: 1 | L6: 1 | M6: 1 | N6: 0 | O6: 0 | P6: 1 | Q6: 0 | R6: 1 | S6: 0 | T6: 0 | U6: 0 | V6: 0 | W6: 0 | X6: 0 | Y6: 0 | Z6: 0 | AA6: 0 | AB6: 0 | AC6: 0 | AD6: 0 | AE6: 0 | AF6: 0 | AG6: 0 | AH6: 0 | AI6: 0 | AJ6: 0 | AK6: 0 | AL6: 0 | AM6: 0 | AN6: 0 | AO6: 0 | AP6: 0 | AQ6: 0 | AR6: 0 | AS6: 0 | AT6: 0 | AU6: 0 | AV6: 1 | AW6: 0 | AX6: 0 | AY6: 0 | AZ6: 0 | BA6: 1 | BB6: 0 | BC6: 0
A7: C6 | B7: 0 | C7: 0 | D7: 0 | E7: 0 | F7: 0 | G7: 0 | H7: 0 | I7: 0 | J7: 0 | K7: 1 | L7: 0 | M7: 0 | N7: 0 | O7: 0 | P7: 1 | Q7: 0 | R7: 0 | S7: 1 | T7: 1 | U7: 1 | V7: 1 | W7: 1 | X7: 1 | Y7: 1 | Z7: 1 | AA7: 1 | AB7: 0 | AC7: 0 | AD7: 0 | AE7: 0 | AF7: 0 | AG7: 0 | AH7: 0 | AI7: 0 | AJ7: 0 | AK7: 0 | AL7: 0 | AM7: 0 | AN7: 0 | AO7: 0 | AP7: 0 | AQ7: 0 | AR7: 0 | AS7: 0 | AT7: 0 | AU7: 0 | AV7: 1 | AW7: 0 | AX7: 0 | AY7: 0 | AZ7: 0 | BA7: 0 | BB7: 0 | BC7: 0
A8: C7 | B8: =+B7 -> 0 | C8: =+C7 -> 0 | D8: =+D7 -> 0 | E8: =+E7 -> 0 | F8: =+F7 -> 0 | G8: =+G7 -> 0 | H8: =+H7 -> 0 | I8: =+I7 -> 0 | J8: =+J7 -> 0 | K8: 1 | L8: =+L7 -> 0 | M8: =+M7 -> 0 | N8: =+N7 -> 0 | O8: =+O7 -> 0 | P8: 1 | Q8: 0 | R8: 0 | S8: =+S7 -> 1 | T8: =+T7 -> 1 | U8: =+U7 -> 1 | V8: =+V7 -> 1 | W8: =+W7 -> 1 | X8: =+X7 -> 1 | Y8: 1 | Z8: 1 | AA8: 1 | AB8: 0 | AC8: 0 | AD8: 0 | AE8: 0 | AF8: 0 | AG8: 0 | AH8: 0 | AI8: 0 | AJ8: 0 | AK8: 0 | AL8: 0 | AM8: 0 | AN8: 0 | AO8: 0 | AP8: 0 | AQ8: 0 | AR8: 0 | AS8: 0 | AT8: 0 | AU8: 0 | AV8: 1 | AW8: 0 | AX8: 0 | AY8: 0 | AZ8: 0 | BA8: 0 | BB8: 0 | BC8: 0
A9: C8 | B9: =+B4 -> 1 | C9: =+C4 -> 1 | D9: =+D4 -> 1 | E9: =+E4 -> 1 | F9: =+F4 -> 1 | G9: =+G4 -> 1 | H9: =+H4 -> 1 | I9: =+I4 -> 1 | ... O9: =+O4 -> 0 | P9: 1 | Q9: 0 | R9: 1 | S9: =+S4 -> 0 | T9: =+T4 -> 0 | U9: =+U4 -> 0 | V9: =+V4 -> 0 | W9: =+W4 -> 0 | X9: =+X4 -> 0 | Y9: 0 | Z9: 0 | AA9: 0 | AB9: 0 | AC9: 0 | AD9: 0 | AE9: 0 | AF9: 0 | AG9: 0 | AH9: 0 | AI9: 0 | AJ9: 0 | AK9: 0 | AL9: 0 | AM9: 0 | AN9: 0 | AO9: 0 | AP9: 0 | AQ9: 0 | AR9: 0 | AS9: 0 | AT9: 0 | AU9: 0 | AV9: 1 | AW9: 0 | AX9: 0 | AY9: 0 | AZ9: 0 | BA9: 1 | BB9: 0 | BC9: 0
A10: C9 | B10: 0 | C10: 0 | D10: 0 | E10: 0 | F10: 0 | G10: 0 | H10: 0 | I10: 0 | J10: 0 | K10: 0 | L10: 0 | M10: 0 | N10: 0 | O10: 0 | P10: 0 | Q10: 0 | R10: 0 | S10: 0 | T10: 0 | U10: 0 | V10: 0 | W10: 0 | X10: 0 | Y10: 0 | Z10: 0 | AA10: 0 | AB10: 0 | AC10: 0 | AD10: 0 | AE10: 0 | AF10: 0 | AG10: 0 | AH10: 0 | AI10: 0 | AJ10: 0 | AK10: 0 | AL10: 0 | AM10: 0 | AN10: 1 | AO10: 1 | AP10: 1 | AQ10: 1 | AR10: 0 | AS10: 1 | AT10: 1 | AU10: 1 | AV10: 0 | AW10: 0 | AX10: 0 | AY10: 0 | AZ10: 0 | BA10: 0 | BB10: 0 | BC10: 0
A11: C10 | B11: 0 | C11: 0 | D11: 0 | E11: 0 | F11: 0 | G11: 0 | H11: 0 | I11: 0 | J11: 0 | K11: 0 | L11: 0 | M11: 0 | N11: 0 | O11: 0 | P11: 0 | Q11: 0 | R11: 0 | S11: 0 | T11: 0 | U11: 0 | V11: 0 | W11: 0 | X11: 0 | Y11: 0 | Z11: 0 | AA11: 0 | AB11: 0 | AC11: 0 | AD11: 0 | AE11: 0 | AF11: 0 | AG11: 0 | AH11: 0 | AI11: 0 | AJ11: 0 | AK11: 0 | AL11: 0 | AM11: 0 | AN11: 1 | AO11: 1 | AP11: 1 | AQ11: 1 | AR11: 1 | AS11: 1 | AT11: 1 | AU11: 1 | AV11: 0 | AW11: 0 | AX11: 0 | AY11: 0 | AZ11: 0 | BA11: 0 | BB11: 0 | BC11: 0
A12: C11 | B12: 0 | C12: 0 | D12: 0 | E12: 0 | F12: 0 | G12: 0 | H12: 0 | I12: 0 | J12: 0 | K12: 0 | L12: 0 | M12: 0 | N12: 0 | O12: 0 | P12: 1 | Q12: 0 | R12: 0 | S12: 0 | T12: 0 | U12: 0 | V12: 0 | W12: 0 | X12: 0 | Y12: 0 | Z12: 0 | AA12: 0 | AB12: 0 | AC12: 0 | AD12: 0 | AE12: 0 | AF12: 0 | AG12: 0 | AH12: 0 | AI12: 0 | AJ12: 0 | AK12: 0 | AL12: 0 | AM12: 0 | AN12: 0 | AO12: 0 | AP12: 0 | AQ12: 0 | AR12: 0 | AS12: 0 | AT12: 0 | AU12: 0 | AV12: 1 | AW12: 0 | AX12: 0 | AY12: 1 | AZ12: 1 | BA12: 0 | BB12: 0 | BC12: 0
A13: C12 | B13: 0 | C13: 0 | D13: 0 | E13: 0 | F13: 0 | G13: 0 | H13: 0 | I13: 0 | J13: 0 | K13: 0 | L13: 0 | M13: 0 | N13: 0 | O13: 0 | P13: 1 | Q13: 0 | R13: 0 | S13: 0 | T13: 0 | U13: 0 | V13: 0 | W13: 0 | X13: 0 | Y13: 0 | Z13: 0 | AA13: 0 | AB13: 0 | AC13: 1 | AD13: 1 | AE13: 1 | AF13: 1 | AG13: 1 | AH13: 1 | AI13: 1 | AJ13: 1 | AK13: 1 | AL13: 1 | AM13: 0 | AN13: 0 | AO13: 0 | AP13: 0 | AQ13: 0 | AR13: 0 | AS13: 0 | AT13: 0 | AU13: 0 | AV13: 0 | AW13: 1 | AX13: 1 | AY13: 0 | AZ13: 0 | BA13: 0 | BB13: 0 | BC13: 0
A16: SEDE 2 | B16: O1 | C16: O2 | D16: O3 | E16: O4 | F16: O5 | G16: O6 | H16: O7 | I16: O8 | J16: O9 | K16: O10 | L16: O11 | M16: O12 | N16: O13 | O16: O14 | P16: O15 | Q16: O16 | R16: O17 | S16: OP1 | T16: OP2 | U16: OP3 | V16: OP4 | W16: OP5 | X16: OP6 | Y16: OP 7 | Z16: OP8 | AA16: OP9 | AB16: OP10 | AC16: E1 | AD16: E2 | AE16: E3 | AF16: E4 | AG16: E5 | AH16: E6 | AI16: E7 | AJ16: E8 | AK16: E9 | AL16: E10 | AM16: E11 | AN16: C1 | AO16: C2 | AP16: C3 | AQ16: C4 | AR16: C5 | AS16: C6 | AT16: C7 | AU16: C8 | AV16: C9 | AW16: L1 | AX16: L2 | AY16: S1 | AZ16: S2 | BA16: E1 | BB16: E2 | BC16: E3
A17: C1 | B17: 0 | C17: 0 | D17: 0 | E17: 0 | F17: 0 | G17: 1 | H17: 0 | I17: 0 | J17: 0 | K17: 1 | L17: 0 | M17: 0 | N17: 0 | O17: 0 | P17: 1 | Q17: 1 | R17: 0 | S17: 0 | T17: 0 | U17: 0 | V17: 0 | W17: 0 | X17: 0 | Y17: 0 | Z17: 0 | AA17: 0 | AB17: 0 | AC17: 0 | AD17: 0 | AE17: 0 | AF17: 0 | AG17: 0 | AH17: 0 | AI17: 0 | AJ17: 0 | AK17: 0 | AL17: 0 | AM17: 0 | AN17: 0 | AO17: 0 | AP17: 0 | AQ17: 0 | AR17: 0 | AS17: 0 | AT17: 0 | AU17: 0 | AV17: 0 | AW17: 0 | AX17: 0 | AY17: 0 | AZ17: 0 | BA17: 0 | BB17: 0 | BC17: 0
A18: C2 | B18: 0 | C18: 0 | D18: 1 | E18: 0 | F18: 0 | G18: 1 | H18: 0 | I18: 0 | J18: 1 | K18: 1 | L18: 1 | M18: 1 | N18: 1 | O18: 1 | P18: 1 | Q18: 1 | R18: 0 | S18: 0 | T18: 0 | U18: 0 | V18: 0 | W18: 0 | X18: 0 | Y18: 0 | Z18: 0 | AA18: 0 | AB18: 0 | AC18: 0 | AD18: 0 | AE18: 0 | AF18: 0 | AG18: 0 | AH18: 0 | AI18: 0 | AJ18: 0 | AK18: 0 | AL18: 0 | AM18: 0 | AN18: 0 | AO18: 0 | AP18: 0 | AQ18: 0 | AR18: 0 | AS18: 0 | AT18: 0 | AU18: 0 | AV18: 0 | AW18: 0 | AX18: 0 | AY18: 0 | AZ18: 0 | BA18: 0 | BB18: 0 | BC18: 0
A19: C3 | B19: 0 | C19: 0 | D19: 1 | E19: 0 | F19: 0 | G19: 1 | H19: 0 | I19: 0 | J19: 1 | K19: 1 | L19: 1 | M19: 1 | N19: 1 | O19: 1 | P19: 1 | Q19: 1 | R19: 0 | S19: 0 | T19: 0 | U19: 0 | V19: 0 | W19: 0 | X19: 0 | Y19: 0 | Z19: 0 | AA19: 0 | AB19: 0 | AC19: 0 | AD19: 0 | AE19: 0 | AF19: 0 | AG19: 0 | AH19: 0 | AI19: 0 | AJ19: 0 | AK19: 0 | AL19: 0 | AM19: 0 | AN19: 0 | AO19: 0 | AP19: 0 | AQ19: 0 | AR19: 0 | AS19: 0 | AT19: 0 | AU19: 0 | AV19: 0 | AW19: 0 | AX19: 0 | AY19: 0 | AZ19: 0 | BA19: 0 | BB19: 0 | BC19: 0
A20: C4 | B20: 0 | C20: 0 | D20: 0 | E20: 0 | F20: 0 | G20: 1 | H20: 0 | I20: 0 | J20: 0 | K20: 1 | L20: 0 | M20: 0 | N20: 0 | O20: 0 | P20: 1 | Q20: 1 | R20: 0 | S20: 0 | T20: 0 | U20: 0 | V20: 0 | W20: 0 | X20: 0 | Y20: 0 | Z20: 0 | AA20: 0 | AB20: 0 | AC20: 0 | AD20: 0 | AE20: 0 | AF20: 0 | AG20: 0 | AH20: 0 | AI20: 0 | AJ20: 0 | AK20: 0 | AL20: 0 | AM20: 0 | AN20: 0 | AO20: 0 | AP20: 0 | AQ20: 0 | AR20: 0 | AS20: 0 | AT20: 0 | AU20: 0 | AV20: 0 | AW20: 0 | AX20: 0 | AY20: 0 | AZ20: 0 | BA20: 0 | BB20: 0 | BC20: 0
A21: C5 | B21: 0 | C21: 0 | D21: 1 | E21: 0 | F21: 0 | G21: 1 | H21: 0 | I21: 0 | J21: 1 | K21: 1 | L21: 1 | M21: 1 | N21: 0 | O21: 0 | P21: 1 | Q21: 1 | R21: 0 | S21: 0 | T21: 0 | U21: 0 | V21: 0 | W21: 0 | X21: 0 | Y21: 0 | Z21: 0 | AA21: 0 | AB21: 0 | AC21: 0 | AD21: 0 | AE21: 0 | AF21: 0 | AG21: 0 | AH21: 0 | AI21: 0 | AJ21: 0 | AK21: 0 | AL21: 0 | AM21: 0 | AN21: 0 | AO21: 0 | AP21: 0 | AQ21: 0 | AR21: 0 | AS21: 0 | AT21: 0 | AU21: 0 | AV21: 0 | AW21: 0 | AX21: 0 | AY21: 0 | AZ21: 0 | BA21: 0 | BB21: 0 | BC21: 0
A22: C6 | B22: 0 | C22: 0 | D22: 1 | E22: 0 | F22: 1 | G22: 1 | H22: 0 | I22: 0 | J22: 1 | K22: 1 | L22: 1 | M22: 1 | N22: 0 | O22: 0 | P22: 0 | Q22: 0 | R22: 0 | S22: 0 | T22: 0 | U22: 0 | V22: 0 | W22: 0 | X22: 0 | Y22: 0 | Z22: 0 | AA22: 0 | AB22: 0 | AC22: 0 | AD22: 0 | AE22: 0 | AF22: 0 | AG22: 0 | AH22: 0 | AI22: 0 | AJ22: 0 | AK22: 0 | AL22: 0 | AM22: 0 | AN22: 0 | AO22: 0 | AP22: 0 | AQ22: 0 | AR22: 0 | AS22: 0 | AT22: 0 | AU22: 0 | AV22: 0 | AW22: 0 | AX22: 0 | AY22: 0 | AZ22: 0 | BA22: 0 | BB22: 0 | BC22: 0
A23: C7 | B23: 0 | C23: 0 | D23: 0 | E23: 0 | F23: 0 | G23: 0 | H23: 0 | I23: 0 | J23: 0 | K23: 1 | L23: 0 | M23: 0 | N23: 0 | O23: 0 | P23: 1 | Q23: 1 | R23: 0 | S23: 1 | T23: 0 | U23: 1 | V23: 0 | W23: 1 | X23: 1 | Y23: 1 | Z23: 0 | AA23: 1 | AB23: 1 | AC23: 0 | AD23: 0 | AE23: 0 | AF23: 0 | AG23: 0 | AH23: 0 | AI23: 0 | AJ23: 0 | AK23: 0 | AL23: 0 | AM23: 0 | AN23: 0 | AO23: 0 | AP23: 0 | AQ23: 0 | AR23: 0 | AS23: 0 | AT23: 0 | AU23: 0 | AV23: 0 | AW23: 0 | AX23: 0 | AY23: 0 | AZ23: 0 | BA23: 0 | BB23: 0 | BC23: 0
A24: C8 | B24: 0 | C24: 0 | D24: 0 | E24: 0 | F24: 0 | G24: 0 | H24: 0 | I24: 0 | J24: 0 | K24: 1 | L24: 0 | M24: 0 | N24: 0 | O24: 0 | P24: 1 | Q24: 1 | R24: 0 | S24: 1 | T24: 0 | U24: 1 | V24: 0 | W24: 1 | X24: 1 | Y24: 1 | Z24: 0 | AA24: 1 | AB24: 1 | AC24: 0 | AD24: 0 | AE24: 0 | AF24: 0 | AG24: 0 | AH24: 0 | AI24: 0 | AJ24: 0 | AK24: 0 | AL24: 0 | AM24: 0 | AN24: 0 | AO24: 0 | AP24: 0 | AQ24: 0 | AR24: 0 | AS24: 0 | AT24: 0 | AU24: 0 | AV24: 0 | AW24: 0 | AX24: 0 | AY24: 0 | AZ24: 0 | BA24: 0 | BB24: 0 | BC24: 0
A25: C9 | B25: 0 | C25: 0 | D25: 0 | E25: 0 | F25: 0 | G25: 0 | H25: 0 | I25: 0 | J25: 0 | K25: 1 | L25: 0 | M25: 0 | N25: 0 | O25: 0 | P25: 1 | Q25: 1 | R25: 0 | S25: 1 | T25: 0 | U25: 1 | V25: 1 | W25: 0 | X25: 1 | Y25: 1 | Z25: 0 | AA25: 1 | AB25: 1 | AC25: 0 | AD25: 0 | AE25: 0 | AF25: 0 | AG25: 0 | AH25: 0 | AI25: 0 | AJ25: 0 | AK25: 0 | AL25: 0 | AM25: 0 | AN25: 0 | AO25: 0 | AP25: 0 | AQ25: 0 | AR25: 0 | AS25: 0 | AT25: 0 | AU25: 0 | AV25: 0 | AW25: 0 | AX25: 0 | AY25: 0 | AZ25: 0 | BA25: 0 | BB25: 0 | BC25: 0
A26: C10 | B26: 0 | C26: 0 | D26: 0 | E26: 0 | F26: 0 | G26: 0 | H26: 0 | I26: 0 | J26: 0 | K26: 1 | L26: 0 | M26: 0 | N26: 0 | O26: 0 | P26: 1 | Q26: 1 | R26: 0 | S26: 0 | T26: 1 | U26: 0 | V26: 0 | W26: 0 | X26: 0 | Y26: 0 | Z26: 0 | AA26: 0 | AB26: 0 | AC26: 0 | AD26: 0 | AE26: 0 | AF26: 0 | AG26: 0 | AH26: 0 | AI26: 0 | AJ26: 0 | AK26: 0 | AL26: 0 | AM26: 0 | AN26: 0 | AO26: 0 | AP26: 0 | AQ26: 0 | AR26: 0 | AS26: 0 | AT26: 0 | AU26: 0 | AV26: 0 | AW26: 0 | AX26: 0 | AY26: 0 | AZ26: 0 | BA26: 0 | BB26: 0 | BC26: 0
A27: C11 | B27: 0 | C27: 0 | D27: 0 | E27: 0 | F27: 0 | G27: 0 | H27: 0 | I27: 0 | J27: 0 | K27: 0 | L27: 0 | M27: 0 | N27: 0 | O27: 0 | P27: 0 | Q27: 0 | R27: 0 | S27: 0 | T27: 0 | U27: 0 | V27: 0 | W27: 0 | X27: 0 | Y27: 0 | Z27: 0 | AA27: 0 | AB27: 0 | AC27: 0 | AD27: 0 | AE27: 0 | AF27: 0 | AG27: 0 | AH27: 0 | AI27: 0 | AJ27: 0 | AK27: 0 | AL27: 0 | AM27: 0 | AN27: 0 | AO27: 0 | AP27: 0 | AQ27: 0 | AR27: 0 | AS27: 0 | AT27: 0 | AU27: 0 | AV27: 0 | AW27: 0 | AX27: 0 | AY27: 0 | AZ27: 0 | BA27: 0 | BB27: 0 | BC27: 0
A28: C12 | B28: 0 | C28: 0 | D28: 0 | E28: 0 | F28: 0 | G28: 0 | H28: 0 | I28: 0 | J28: 0 | K28: 0 | L28: 0 | M28: 0 | N28: 0 | O28: 0 | P28: 0 | Q28: 0 | R28: 0 | S28: 0 | T28: 0 | U28: 0 | V28: 0 | W28: 0 | X28: 0 | Y28: 0 | Z28: 0 | AA28: 0 | AB28: 0 | AC28: 0 | AD28: 0 | AE28: 0 | AF28: 0 | AG28: 0 | AH28: 0 | AI28: 0 | AJ28: 0 | AK28: 0 | AL28: 0 | AM28: 0 | AN28: 0 | AO28: 0 | AP28: 0 | AQ28: 0 | AR28: 0 | AS28: 0 | AT28: 0 | AU28: 0 | AV28: 0 | AW28: 0 | AX28: 0 | AY28: 0 | AZ28: 0 | BA28: 0 | BB28: 0 | BC28: 0
A31: SEDE 3 | B31: O1 | C31: O2 | D31: O3 | E31: O4 | F31: O5 | G31: O6 | H31: O7 | I31: O8 | J31: O9 | K31: O10 | L31: O11 | M31: O12 | N31: O13 | O31: O14 | P31: O15 | Q31: O16 | R31: O17 | S31: OP1 | T31: OP2 | U31: OP3 | V31: OP4 | W31: OP5 | X31: OP6 | Y31: OP 7 | Z31: OP8 | AA31: OP9 | AB31: OP10 | AC31: E1 | AD31: E2 | AE31: E3 | AF31: E4 | AG31: E5 | AH31: E6 | AI31: E7 | AJ31: E8 | AK31: E9 | AL31: E10 | AM31: E11 | AN31: C1 | AO31: C2 | AP31: C3 | AQ31: C4 | AR31: C5 | AS31: C6 | AT31: C7 | AU31: C8 | AV31: C9 | AW31: L1 | AX31: L2 | AY31: S1 | AZ31: S2 | BA31: E1 | BB31: E2 | BC31: E3
A32: C1 | B32: 0 | C32: 0 | D32: 0 | E32: 0 | F32: 0 | G32: 1 | H32: 0 | I32: 0 | J32: 1 | K32: 1 | L32: 1 | M32: 0 | N32: 0 | O32: 0 | P32: 0 | Q32: 0 | R32: 1 | S32: 0 | T32: 0 | U32: 0 | V32: 0 | W32: 0 | X32: 0 | Y32: 0 | Z32: 0 | AA32: 0 | AB32: 0 | AC32: 0 | AD32: 0 | AE32: 0 | AF32: 0 | AG32: 0 | AH32: 0 | AI32: 0 | AJ32: 0 | AK32: 0 | AL32: 0 | AM32: 0 | AN32: 0 | AO32: 0 | AP32: 0 | AQ32: 0 | AR32: 0 | AS32: 0 | AT32: 0 | AU32: 0 | AV32: 0 | AW32: 0 | AX32: 0 | AY32: 0 | AZ32: 0 | BA32: 0 | BB32: 0 | BC32: 0
